Workbook
Name FRUTAS: PACIENTES!$A$4:$D$34
Name salidanutricion: 'NUTRICIÓN CLÍNICA'!$A$4:$D$14

Sheet GENERAL
B1: DESCRIPCIÓN | C1: UNIDAD DE MEDIDA | D1: 1 | E1: 2 | F1: 3 | G1: 4 | H1: 5 | I1: 6 | J1: 7 | K1: 8 | L1: 9 | M1: 10 | N1: 11 | O1: 12 | P1: 13 | Q1: 14 | R1: 15 | S1: 16 | T1: 17 | U1: 18 | V1: 19 | W1: 20 | X1: 21 | Y1: 22 | Z1: 23 | AA1: 24 | AB1: 25 | AC1: 26 | AD1: 27 | AE1: 28 | AF1: 29 | AG1: 30 | AH1: 31 | AI1: TOTAL
A3: GRUPO DE ALIMENTO: FRUTA
A4: 2212004001 | B4: CIRUELA ROJA | C4: KG | D4: =SUM(PACIENTES!D4+COMEDOR!D4+JORNADA!N4+'DIETOLOGÍA(S)'!D4) -> 0 | E4: =SUM(PACIENTES!E4+COMEDOR!E4+JORNADA!E4+'DIETOLOGÍA(S)'!E4) -> 0 | F4: =SUM(PACIENTES!F4+COMEDOR!F4+JORNADA!F4+'DIETOLOGÍA(S)'!F4) -> 0 | G4: =SUM(PACIENTES!G4+COMEDOR!G4+JORNADA!G4+'DIETOLOGÍA(S)'!G4) -> 0 | H4: =SUM(PACIENTES!H4+COMEDOR!H4+JORNADA!H4+'DIETOLOGÍA(S)'!H4) -> 0 | I4: =SUM(PACIENTES!I4+COMEDOR!I4+JORNADA!I4+'DIETOLOGÍA(S)'!I4) -> 0 | J4: =SUM(PACIENTES!J4+COMEDOR!J4+JORNADA!J4+'DIETOLOGÍA(S)'!J4) -> 1 | K4: =SUM(PACIENTES!K4+COMEDOR!K4+JORNADA!K4+'DIETOLOGÍA(S)'!K4) -> 0 | L4: =SUM(PACIENTES!L4+COMEDOR!L4+JORNADA!L4+'DIETOLOGÍA(S)'!L4) -> 0 | ... AH4: =SUM(PACIENTES!AH4+COMEDOR!AH4+JORNADA!AH4+'DIETOLOGÍA(S)'!AH4) -> 0 | AI4: =SUM(D4:AH4) -> 2
A5: 2212004002 | B5: CAÑA DE AZUCAR | C5: PIEZA | D5: =SUM(PACIENTES!D5+COMEDOR!D5+JORNADA!N5+'DIETOLOGÍA(S)'!D5) -> 0 | E5: =SUM(PACIENTES!E5+COMEDOR!E5+JORNADA!E5+'DIETOLOGÍA(S)'!E5) -> 0 | F5: =SUM(PACIENTES!F5+COMEDOR!F5+JORNADA!F5+'DIETOLOGÍA(S)'!F5) -> 0 | G5: =SUM(PACIENTES!G5+COMEDOR!G5+JORNADA!G5+'DIETOLOGÍA(S)'!G5) -> 0 | H5: =SUM(PACIENTES!H5+COMEDOR!H5+JORNADA!H5+'DIETOLOGÍA(S)'!H5) -> 0 | I5: =SUM(PACIENTES!I5+COMEDOR!I5+JORNADA!I5+'DIETOLOGÍA(S)'!I5) -> 0 | J5: =SUM(PACIENTES!J5+COMEDOR!J5+JORNADA!J5+'DIETOLOGÍA(S)'!J5) -> 0 | K5: =SUM(PACIENTES!K5+COMEDOR!K5+JORNADA!K5+'DIETOLOGÍA(S)'!K5) -> 0 | L5: =SUM(PACIENTES!L5+COMEDOR!L5+JORNADA!L5+'DIETOLOGÍA(S)'!L5) -> 0 | ... AH5: =SUM(PACIENTES!AH5+COMEDOR!AH5+JORNADA!AH5+'DIETOLOGÍA(S)'!AH5) -> 0 | AI5: =SUM(D5:AH5) -> 0
A6: 2212004003 | B6: CIRUELA AMARILLA | C6: KG | D6: =SUM(PACIENTES!D6+COMEDOR!D6+JORNADA!D6+'DIETOLOGÍA(S)'!D6) -> 0 | E6: =SUM(PACIENTES!E6+COMEDOR!E6+JORNADA!E6+'DIETOLOGÍA(S)'!E6) -> 0 | F6: =SUM(PACIENTES!F7+COMEDOR!F7+JORNADA!F7+'DIETOLOGÍA(S)'!F7) -> 0 | G6: =SUM(PACIENTES!G6+COMEDOR!G6+JORNADA!G6+'DIETOLOGÍA(S)'!G6) -> 0 | H6: =SUM(PACIENTES!H6+COMEDOR!H6+JORNADA!H6+'DIETOLOGÍA(S)'!H6) -> 0 | I6: =SUM(PACIENTES!I6+COMEDOR!I6+JORNADA!I6+'DIETOLOGÍA(S)'!I6) -> 0 | J6: =SUM(PACIENTES!J6+COMEDOR!J6+JORNADA!J6+'DIETOLOGÍA(S)'!J6) -> 0 | K6: =SUM(PACIENTES!K6+COMEDOR!K6+JORNADA!K6+'DIETOLOGÍA(S)'!K6) -> 0 | L6: =SUM(PACIENTES!L6+COMEDOR!L6+JORNADA!L6+'DIETOLOGÍA(S)'!L6) -> 0 | M6: =SUM(PACIENTES!M6+COMEDOR!M6+JORNADA!M6+'DIETOLOGÍA(S)'!M6) -> 0 | N6: =SUM(PACIENTES!N6+COMEDOR!N6+JORNADA!N6+'DIETOLOGÍA(S)'!N6) -> 0 | ... AH6: =SUM(PACIENTES!AH6+COMEDOR!AH6+JORNADA!AH6+'DIETOLOGÍA(S)'!AH6) -> 0 | AI6: =SUM(D6:AH6) -> 0
A7: 2212004004 | B7: DURAZNO | C7: KG | D7: =SUM(PACIENTES!D7+COMEDOR!D7+JORNADA!D7+'DIETOLOGÍA(S)'!D7) -> 30 | E7: =SUM(PACIENTES!E7+COMEDOR!E7+JORNADA!E7+'DIETOLOGÍA(S)'!E7) -> 70 | F7: =SUM(PACIENTES!F7+COMEDOR!F7+JORNADA!F7+'DIETOLOGÍA(S)'!F7) -> 0 | G7: =SUM(PACIENTES!G7+COMEDOR!G7+JORNADA!G7+'DIETOLOGÍA(S)'!G7) -> 40 | H7: =SUM(PACIENTES!H7+COMEDOR!H7+JORNADA!H7+'DIETOLOGÍA(S)'!H7) -> 0 | I7: =SUM(PACIENTES!I7+COMEDOR!I7+JORNADA!I7+'DIETOLOGÍA(S)'!I7) -> 2 | J7: =SUM(PACIENTES!J7+COMEDOR!J7+JORNADA!J7+'DIETOLOGÍA(S)'!J7) -> 1 | K7: =SUM(PACIENTES!K7+COMEDOR!K7+JORNADA!K7+'DIETOLOGÍA(S)'!K7) -> 0 | ... AH7: =SUM(PACIENTES!AH7+COMEDOR!AH7+JORNADA!AH7+'DIETOLOGÍA(S)'!AH7) -> 0 | AI7: =SUM(D7:AH7) -> 267
A8: 2212004005 | B8: FRESA | C8: KG | D8: =SUM(PACIENTES!D8+COMEDOR!D8+JORNADA!D8+'DIETOLOGÍA(S)'!D8) -> 0 | E8: =SUM(PACIENTES!E8+COMEDOR!E8+JORNADA!E8+'DIETOLOGÍA(S)'!E8) -> 0 | F8: =SUM(PACIENTES!F8+COMEDOR!F8+JORNADA!F8+'DIETOLOGÍA(S)'!F8) -> 0 | G8: =SUM(PACIENTES!G8+COMEDOR!G8+JORNADA!G8+'DIETOLOGÍA(S)'!G8) -> 0 | H8: =SUM(PACIENTES!H8+COMEDOR!H8+JORNADA!H8+'DIETOLOGÍA(S)'!H8) -> 0 | I8: =SUM(PACIENTES!I8+COMEDOR!I8+JORNADA!I8+'DIETOLOGÍA(S)'!I8) -> 1 | J8: =SUM(PACIENTES!J8+COMEDOR!J8+JORNADA!J8+'DIETOLOGÍA(S)'!J8) -> 1 | K8: =SUM(PACIENTES!K8+COMEDOR!K8+JORNADA!K8+'DIETOLOGÍA(S)'!K8) -> 0 | ... AH8: =SUM(PACIENTES!AH8+COMEDOR!AH8+JORNADA!AH8+'DIETOLOGÍA(S)'!AH8) -> 0 | AI8: =SUM(D8:AH8) -> 11
A9: 2212004006 | B9: GUAYABA | C9: KG | D9: =SUM(PACIENTES!D9+COMEDOR!D9+JORNADA!D9+'DIETOLOGÍA(S)'!D9) -> 0 | E9: =SUM(PACIENTES!E9+COMEDOR!E9+JORNADA!E9+'DIETOLOGÍA(S)'!E9) -> 30 | F9: =SUM(PACIENTES!F9+COMEDOR!F9+JORNADA!F9+'DIETOLOGÍA(S)'!F9) -> 25 | G9: =SUM(PACIENTES!G9+COMEDOR!G9+JORNADA!G9+'DIETOLOGÍA(S)'!G9) -> 0 | H9: =SUM(PACIENTES!H9+COMEDOR!H9+JORNADA!H9+'DIETOLOGÍA(S)'!H9) -> 30 | I9: =SUM(PACIENTES!I9+COMEDOR!I9+JORNADA!I9+'DIETOLOGÍA(S)'!I9) -> 0 | J9: =SUM(PACIENTES!J9+COMEDOR!J9+JORNADA!J9+'DIETOLOGÍA(S)'!J9) -> 1 | K9: =SUM(PACIENTES!K9+COMEDOR!K9+JORNADA!K9+'DIETOLOGÍA(S)'!K9) -> 0 | ... AH9: =SUM(PACIENTES!AH9+COMEDOR!AH9+JORNADA!AH9+'DIETOLOGÍA(S)'!AH9) -> 0 | AI9: =SUM(D9:AH9) -> 359
A10: 2212004007 | B10: JICAMA | C10: KG | D10: =SUM(PACIENTES!D10+COMEDOR!D10+JORNADA!D10+'DIETOLOGÍA(S)'!D10) -> 0 | E10: =SUM(PACIENTES!E10+COMEDOR!E10+JORNADA!E10+'DIETOLOGÍA(S)'!E10) -> 0 | F10: =SUM(PACIENTES!F10+COMEDOR!F10+JORNADA!F10+'DIETOLOGÍA(S)'!F10) -> 0 | G10: =SUM(PACIENTES!G10+COMEDOR!G10+JORNADA!G10+'DIETOLOGÍA(S)'!G10) -> 0 | H10: =SUM(PACIENTES!H10+COMEDOR!H10+JORNADA!H10+'DIETOLOGÍA(S)'!H10) -> 0 | I10: =SUM(PACIENTES!I10+COMEDOR!I10+JORNADA!I10+'DIETOLOGÍA(S)'!I10) -> 2 | J10: =SUM(PACIENTES!J10+COMEDOR!J10+JORNADA!J10+'DIETOLOGÍA(S)'!J10) -> 2 | K10: =SUM(PACIENTES!K10+COMEDOR!K10+JORNADA!K10+'DIETOLOGÍA(S)'!K10) -> 0 | ... AH10: =SUM(PACIENTES!AH10+COMEDOR!AH10+JORNADA!AH10+'DIETOLOGÍA(S)'!AH10) -> 0 | AI10: =SUM(D10:AH10) -> 16
A11: 2212004008 | B11: LIMA | C11: KG | D11: =SUM(PACIENTES!D11+COMEDOR!D11+JORNADA!D11+'DIETOLOGÍA(S)'!D11) -> 0 | E11: =SUM(PACIENTES!E11+COMEDOR!E11+JORNADA!E11+'DIETOLOGÍA(S)'!E11) -> 0 | F11: =SUM(PACIENTES!F11+COMEDOR!F11+JORNADA!F11+'DIETOLOGÍA(S)'!F11) -> 0 | G11: =SUM(PACIENTES!G11+COMEDOR!G11+JORNADA!G11+'DIETOLOGÍA(S)'!G11) -> 0 | H11: =SUM(PACIENTES!H11+COMEDOR!H11+JORNADA!H11+'DIETOLOGÍA(S)'!H11) -> 0 | I11: =SUM(PACIENTES!I11+COMEDOR!I11+JORNADA!I11+'DIETOLOGÍA(S)'!I11) -> 0 | J11: =SUM(PACIENTES!J11+COMEDOR!J11+JORNADA!J11+'DIETOLOGÍA(S)'!J11) -> 0 | K11: =SUM(PACIENTES!K11+COMEDOR!K11+JORNADA!K11+'DIETOLOGÍA(S)'!K11) -> 0 | ... AH11: =SUM(PACIENTES!AH11+COMEDOR!AH11+JORNADA!AH11+'DIETOLOGÍA(S)'!AH11) -> 0 | AI11: =SUM(D11:AH11) -> 0
A12: 2212004009 | B12: MANDARINA | C12: KG | D12: =SUM(PACIENTES!D12+COMEDOR!D12+JORNADA!D12+'DIETOLOGÍA(S)'!D12) -> 0 | E12: =SUM(PACIENTES!E12+COMEDOR!E12+JORNADA!E12+'DIETOLOGÍA(S)'!E12) -> 0 | F12: =SUM(PACIENTES!F12+COMEDOR!F12+JORNADA!F12+'DIETOLOGÍA(S)'!F12) -> 0 | G12: =SUM(PACIENTES!G12+COMEDOR!G12+JORNADA!G12+'DIETOLOGÍA(S)'!G12) -> 0 | H12: =SUM(PACIENTES!H12+COMEDOR!H12+JORNADA!H12+'DIETOLOGÍA(S)'!H12) -> 0 | I12: =SUM(PACIENTES!I12+COMEDOR!I12+JORNADA!I12+'DIETOLOGÍA(S)'!I12) -> 0 | J12: =SUM(PACIENTES!J12+COMEDOR!J12+JORNADA!J12+'DIETOLOGÍA(S)'!J12) -> 2 | K12: =SUM(PACIENTES!K12+COMEDOR!K12+JORNADA!K12+'DIETOLOGÍA(S)'!K12) -> 0 | ... AH12: =SUM(PACIENTES!AH12+COMEDOR!AH12+JORNADA!AH12+'DIETOLOGÍA(S)'!AH12) -> 0 | AI12: =SUM(D12:AH12) -> 8
A13: 2212004011 | B13: MANZANA DELICIA | C13: KG | D13: =SUM(PACIENTES!D13+COMEDOR!D13+JORNADA!D13+'DIETOLOGÍA(S)'!D13+'NUTRICIÓN CLÍNICA'!D4) -> 27 | E13: =SUM(PACIENTES!E13+COMEDOR!E13+JORNADA!E13+'DIETOLOGÍA(S)'!E13+'NUTRICIÓN CLÍNICA'!E4) -> 42 | F13: =SUM(PACIENTES!F13+COMEDOR!F13+JORNADA!F13+'DIETOLOGÍA(S)'!F13+'NUTRICIÓN CLÍNICA'!F4) -> 79 | G13: =SUM(PACIENTES!G13+COMEDOR!G13+JORNADA!G13+'DIETOLOGÍA(S)'!G13+'NUTRICIÓN CLÍNICA'!G4) -> 69 | H13: =SUM(PACIENTES!H13+COMEDOR!H13+JORNADA!H13+'DIETOLOGÍA(S)'!H13+'NUTRICIÓN CLÍNICA'!H4) -> 64 | I13: =SUM(PACIENTES!I13+COMEDOR!I13+JORNADA!I13+'DIETOLOGÍA(S)'!I13+'NUTRICIÓN CLÍNICA'!I4) -> 36 | J13: =SUM(PACIENTES!J13+COMEDOR!J13+JORNADA!J13+'DIETOLOGÍA(S)'!J13+'NUTRICIÓN CLÍNICA'!J4) -> 8 | K13: =SUM(PACIENTES!K13+COMEDOR!K13+JORNADA!K13+'DIETOLOGÍA(S)'!K13+'NUTRICIÓN CLÍNICA'!K4) -> 59 | ... AH13: =SUM(PACIENTES!AH13+COMEDOR!AH13+JORNADA!AH13+'DIETOLOGÍA(S)'!AH13+'NUTRICIÓN CLÍNICA'!AH4) -> 4 | AI13: =SUM(D13:AH13) -> 1281
A14: 2212004012 | B14: MANZANA GOLDEN | C14: KG | D14: =SUM(PACIENTES!D14+COMEDOR!D14+JORNADA!D14+'DIETOLOGÍA(S)'!D14) -> 15 | E14: =SUM(PACIENTES!E14+COMEDOR!E14+JORNADA!E14+'DIETOLOGÍA(S)'!E14) -> 15 | F14: =SUM(PACIENTES!F14+COMEDOR!F14+JORNADA!F14+'DIETOLOGÍA(S)'!F14) -> 0 | G14: =SUM(PACIENTES!G14+COMEDOR!G14+JORNADA!G14+'DIETOLOGÍA(S)'!G14) -> 0 | H14: =SUM(PACIENTES!H14+COMEDOR!H14+JORNADA!H14+'DIETOLOGÍA(S)'!H14) -> 15 | I14: =SUM(PACIENTES!I14+COMEDOR!I14+JORNADA!I14+'DIETOLOGÍA(S)'!I14) -> 60 | J14: =SUM(PACIENTES!J14+COMEDOR!J14+JORNADA!J14+'DIETOLOGÍA(S)'!J14) -> 64 | K14: =SUM(PACIENTES!K14+COMEDOR!K14+JORNADA!K14+'DIETOLOGÍA(S)'!K14) -> 15 | ... AH14: =SUM(PACIENTES!AH14+COMEDOR!AH14+JORNADA!AH14+'DIETOLOGÍA(S)'!AH14) -> 70 | AI14: =SUM(D14:AH14) -> 1261
A15: 2212004013 | B15: MELON CANTALUP | C15: KG | D15: =SUM(PACIENTES!D15+COMEDOR!D15+JORNADA!D15+'DIETOLOGÍA(S)'!D15) -> 50 | E15: =SUM(PACIENTES!E15+COMEDOR!E15+JORNADA!E15+'DIETOLOGÍA(S)'!E15) -> 0 | F15: =SUM(PACIENTES!F15+COMEDOR!F15+JORNADA!F15+'DIETOLOGÍA(S)'!F15) -> 0 | G15: =SUM(PACIENTES!G15+COMEDOR!G15+JORNADA!G15+'DIETOLOGÍA(S)'!G15) -> 70 | H15: =SUM(PACIENTES!H15+COMEDOR!H15+JORNADA!H15+'DIETOLOGÍA(S)'!H15) -> 50 | I15: =SUM(PACIENTES!I15+COMEDOR!I15+JORNADA!I15+'DIETOLOGÍA(S)'!I15) -> 2 | J15: =SUM(PACIENTES!J15+COMEDOR!J15+JORNADA!J15+'DIETOLOGÍA(S)'!J15) -> 2 | K15: =SUM(PACIENTES!K15+COMEDOR!K15+JORNADA!K15+'DIETOLOGÍA(S)'!K15) -> 0 | ... AH15: =SUM(PACIENTES!AH15+COMEDOR!AH15+JORNADA!AH15+'DIETOLOGÍA(S)'!AH15) -> 30 | AI15: =SUM(D15:AH15) -> 482
A16: 2212004014 | B16: NARANJA | C16: KG | D16: =SUM(PACIENTES!D16+COMEDOR!D16+JORNADA!D16+'DIETOLOGÍA(S)'!D16) -> 0 | E16: =SUM(PACIENTES!E16+COMEDOR!E16+JORNADA!E16+'DIETOLOGÍA(S)'!E16) -> 0 | F16: =SUM(PACIENTES!F16+COMEDOR!F16+JORNADA!F16+'DIETOLOGÍA(S)'!F16) -> 0 | G16: =SUM(PACIENTES!G16+COMEDOR!G16+JORNADA!G16+'DIETOLOGÍA(S)'!G16) -> 0 | H16: =SUM(PACIENTES!H16+COMEDOR!H16+JORNADA!H16+'DIETOLOGÍA(S)'!H16) -> 35 | I16: =SUM(PACIENTES!I16+COMEDOR!I16+JORNADA!I16+'DIETOLOGÍA(S)'!I16) -> 1 | J16: =SUM(PACIENTES!J16+COMEDOR!J16+JORNADA!J16+'DIETOLOGÍA(S)'!J16) -> 7 | K16: =SUM(PACIENTES!K16+COMEDOR!K16+JORNADA!K16+'DIETOLOGÍA(S)'!K16) -> 0 | ... AH16: =SUM(PACIENTES!AH16+COMEDOR!AH16+JORNADA!AH16+'DIETOLOGÍA(S)'!AH16) -> 0 | AI16: =SUM(D16:AH16) -> 242
A17: 2212004015 | B17: PAPAYA | C17: KG | D17: =SUM(PACIENTES!D17+COMEDOR!D17+JORNADA!D17+'DIETOLOGÍA(S)'!D17) -> 44 | E17: =SUM(PACIENTES!E17+COMEDOR!E17+JORNADA!E17+'DIETOLOGÍA(S)'!E17) -> 57 | F17: =SUM(PACIENTES!F17+COMEDOR!F17+JORNADA!F17+'DIETOLOGÍA(S)'!F17) -> 50 | G17: =SUM(PACIENTES!G17+COMEDOR!G17+JORNADA!G17+'DIETOLOGÍA(S)'!G17) -> 0 | H17: =SUM(PACIENTES!H17+COMEDOR!H17+JORNADA!H17+'DIETOLOGÍA(S)'!H17) -> 44 | I17: =SUM(PACIENTES!I17+COMEDOR!I17+JORNADA!I17+'DIETOLOGÍA(S)'!I17) -> 54 | J17: =SUM(PACIENTES!J17+COMEDOR!J17+JORNADA!J17+'DIETOLOGÍA(S)'!J17) -> 59 | K17: =SUM(PACIENTES!K17+COMEDOR!K17+JORNADA!K17+'DIETOLOGÍA(S)'!K17) -> 44 | ... AH17: =SUM(PACIENTES!AH17+COMEDOR!AH17+JORNADA!AH17+'DIETOLOGÍA(S)'!AH17) -> 60 | AI17: =SUM(D17:AH17) -> 1486
A18: 2212004016 | B18: PERA | C18: KG | D18: =SUM(PACIENTES!D18+COMEDOR!D18+JORNADA!D18+'DIETOLOGÍA(S)'!D18) -> 0 | E18: =SUM(PACIENTES!E18+COMEDOR!E18+JORNADA!E18+'DIETOLOGÍA(S)'!E18) -> 0 | F18: =SUM(PACIENTES!F18+COMEDOR!F18+JORNADA!F18+'DIETOLOGÍA(S)'!F18) -> 0 | G18: =SUM(PACIENTES!G18+COMEDOR!G18+JORNADA!G18+'DIETOLOGÍA(S)'!G18) -> 60 | H18: =SUM(PACIENTES!H18+COMEDOR!H18+JORNADA!H18+'DIETOLOGÍA(S)'!H18) -> 0 | I18: =SUM(PACIENTES!I18+COMEDOR!I18+JORNADA!I18+'DIETOLOGÍA(S)'!I18) -> 0 | J18: =SUM(PACIENTES!J18+COMEDOR!J18+JORNADA!J18+'DIETOLOGÍA(S)'!J18) -> 0 | K18: =SUM(PACIENTES!K18+COMEDOR!K18+JORNADA!K18+'DIETOLOGÍA(S)'!K18) -> 0 | ... AH18: =SUM(PACIENTES!AH18+COMEDOR!AH18+JORNADA!AH18+'DIETOLOGÍA(S)'!AH18) -> 50 | AI18: =SUM(D18:AH18) -> 325
A19: 2212004017 | B19: PERA MANTEQUILLA | C19: KG | D19: =SUM(PACIENTES!D19+COMEDOR!D19+JORNADA!D19+'DIETOLOGÍA(S)'!D19) -> 65 | E19: =SUM(PACIENTES!E19+COMEDOR!E19+JORNADA!E19+'DIETOLOGÍA(S)'!E19) -> 30 | F19: =SUM(PACIENTES!F19+COMEDOR!F19+JORNADA!F19+'DIETOLOGÍA(S)'!F19) -> 30 | G19: =SUM(PACIENTES!G19+COMEDOR!G19+JORNADA!G19+'DIETOLOGÍA(S)'!G19) -> 0 | H19: =SUM(PACIENTES!H19+COMEDOR!H19+JORNADA!H19+'DIETOLOGÍA(S)'!H19) -> 55 | I19: =SUM(PACIENTES!I19+COMEDOR!I19+JORNADA!I19+'DIETOLOGÍA(S)'!I19) -> 46 | J19: =SUM(PACIENTES!J19+COMEDOR!J19+JORNADA!J19+'DIETOLOGÍA(S)'!J19) -> 77 | K19: =SUM(PACIENTES!K19+COMEDOR!K19+JORNADA!K19+'DIETOLOGÍA(S)'!K19) -> 80 | ... AH19: =SUM(PACIENTES!AH19+COMEDOR!AH19+JORNADA!AH19+'DIETOLOGÍA(S)'!AH19) -> 20 | AI19: =SUM(D19:AH19) -> 1508
A20: 2212004018 | B20: PIÑA | C20: KG | D20: =SUM(PACIENTES!D20+COMEDOR!D20+JORNADA!D20+'DIETOLOGÍA(S)'!D20) -> 86 | E20: =SUM(PACIENTES!E20+COMEDOR!E20+JORNADA!E20+'DIETOLOGÍA(S)'!E20) -> 52 | F20: =SUM(PACIENTES!F20+COMEDOR!F20+JORNADA!F20+'DIETOLOGÍA(S)'!F20) -> 40 | G20: =SUM(PACIENTES!G20+COMEDOR!G20+JORNADA!G20+'DIETOLOGÍA(S)'!G20) -> 30 | H20: =SUM(PACIENTES!H20+COMEDOR!H20+JORNADA!H20+'DIETOLOGÍA(S)'!H20) -> 60 | I20: =SUM(PACIENTES!I20+COMEDOR!I20+JORNADA!I20+'DIETOLOGÍA(S)'!I20) -> 28 | J20: =SUM(PACIENTES!J20+COMEDOR!J20+JORNADA!J20+'DIETOLOGÍA(S)'!J20) -> 30 | K20: =SUM(PACIENTES!K20+COMEDOR!K20+JORNADA!K20+'DIETOLOGÍA(S)'!K20) -> 0 | ... AH20: =SUM(PACIENTES!AH20+COMEDOR!AH20+JORNADA!AH20+'DIETOLOGÍA(S)'!AH20) -> 30 | AI20: =SUM(D20:AH20) -> 1028
A21: 2212004019 | B21: PLATANO MACHO | C21: KG | D21: =SUM(PACIENTES!D21+COMEDOR!D21+JORNADA!D21+'DIETOLOGÍA(S)'!D21) -> 0 | E21: =SUM(PACIENTES!E21+COMEDOR!E21+JORNADA!E21+'DIETOLOGÍA(S)'!E21) -> 0 | F21: =SUM(PACIENTES!F21+COMEDOR!F21+JORNADA!F21+'DIETOLOGÍA(S)'!F21) -> 0 | G21: =SUM(PACIENTES!G21+COMEDOR!G21+JORNADA!G21+'DIETOLOGÍA(S)'!G21) -> 0 | H21: =SUM(PACIENTES!H21+COMEDOR!H21+JORNADA!H21+'DIETOLOGÍA(S)'!H21) -> 0 | I21: =SUM(PACIENTES!I21+COMEDOR!I21+JORNADA!I21+'DIETOLOGÍA(S)'!I21) -> 0 | J21: =SUM(PACIENTES!J21+COMEDOR!J21+JORNADA!J21+'DIETOLOGÍA(S)'!J21) -> 2 | K21: =SUM(PACIENTES!K21+COMEDOR!K21+JORNADA!K21+'DIETOLOGÍA(S)'!K21) -> 30 | ... AH21: =SUM(PACIENTES!AH21+COMEDOR!AH21+JORNADA!AH21+'DIETOLOGÍA(S)'!AH21) -> 0 | AI21: =SUM(D21:AH21) -> 154
A22: 2212004020 | B22: PLATANO ROATAN | C22: KG | D22: =SUM(PACIENTES!D22+COMEDOR!D22+JORNADA!D22+'DIETOLOGÍA(S)'!D22+'NUTRICIÓN CLÍNICA'!D5) -> 85 | E22: =SUM(PACIENTES!E22+COMEDOR!E22+JORNADA!E22+'DIETOLOGÍA(S)'!E22+'NUTRICIÓN CLÍNICA'!E5) -> 85 | F22: =SUM(PACIENTES!F22+COMEDOR!F22+JORNADA!F22+'DIETOLOGÍA(S)'!F22+'NUTRICIÓN CLÍNICA'!F5) -> 30 | G22: =SUM(PACIENTES!G22+COMEDOR!G22+JORNADA!G22+'DIETOLOGÍA(S)'!G22+'NUTRICIÓN CLÍNICA'!G5) -> 35 | H22: =SUM(PACIENTES!H22+COMEDOR!H22+JORNADA!H22+'DIETOLOGÍA(S)'!H22+'NUTRICIÓN CLÍNICA'!H5) -> 42 | I22: =SUM(PACIENTES!I22+COMEDOR!I22+JORNADA!I22+'DIETOLOGÍA(S)'!I22+'NUTRICIÓN CLÍNICA'!I5) -> 57 | J22: =SUM(PACIENTES!J22+COMEDOR!J22+JORNADA!J22+'DIETOLOGÍA(S)'!J22+'NUTRICIÓN CLÍNICA'!J5) -> 56 | K22: =SUM(PACIENTES!K22+COMEDOR!K22+JORNADA!K22+'DIETOLOGÍA(S)'!K22+'NUTRICIÓN CLÍNICA'!K5) -> 95 | ... AH22: =SUM(PACIENTES!AH22+COMEDOR!AH22+JORNADA!AH22+'DIETOLOGÍA(S)'!AH22+'NUTRICIÓN CLÍNICA'!AH5) -> 5 | AI22: =SUM(D22:AH22) -> 1705
A23: 2212004021 | B23: SANDIA | C23: KG | D23: =SUM(PACIENTES!D23+COMEDOR!D23+JORNADA!D23+'DIETOLOGÍA(S)'!D23) -> 0 | E23: =SUM(PACIENTES!E23+COMEDOR!E23+JORNADA!E23+'DIETOLOGÍA(S)'!E23) -> 0 | F23: =SUM(PACIENTES!F23+COMEDOR!F23+JORNADA!F23+'DIETOLOGÍA(S)'!F23) -> 0 | G23: =SUM(PACIENTES!G23+COMEDOR!G23+JORNADA!G23+'DIETOLOGÍA(S)'!G23) -> 30 | H23: =SUM(PACIENTES!H23+COMEDOR!H23+JORNADA!H23+'DIETOLOGÍA(S)'!H23) -> 0 | I23: =SUM(PACIENTES!I23+COMEDOR!I23+JORNADA!I23+'DIETOLOGÍA(S)'!I23) -> 2 | J23: =SUM(PACIENTES!J23+COMEDOR!J23+JORNADA!J23+'DIETOLOGÍA(S)'!J23) -> 2 | K23: =SUM(PACIENTES!K23+COMEDOR!K23+JORNADA!K23+'DIETOLOGÍA(S)'!K23) -> 0 | ... AH23: =SUM(PACIENTES!AH23+COMEDOR!AH23+JORNADA!AH23+'DIETOLOGÍA(S)'!AH23) -> 25 | AI23: =SUM(D23:AH23) -> 187
A24: 2212004022 | B24: TEJOCOTE | C24: KG | D24: =SUM(PACIENTES!D24+COMEDOR!D24+JORNADA!D24+'DIETOLOGÍA(S)'!D24) -> 0 | E24: =SUM(PACIENTES!E24+COMEDOR!E24+JORNADA!E24+'DIETOLOGÍA(S)'!E24) -> 0 | F24: =SUM(PACIENTES!F24+COMEDOR!F24+JORNADA!F24+'DIETOLOGÍA(S)'!F24) -> 0 | G24: =SUM(PACIENTES!G24+COMEDOR!G24+JORNADA!G24+'DIETOLOGÍA(S)'!G24) -> 0 | H24: =SUM(PACIENTES!H24+COMEDOR!H24+JORNADA!H24+'DIETOLOGÍA(S)'!H24) -> 0 | I24: =SUM(PACIENTES!I24+COMEDOR!I24+JORNADA!I24+'DIETOLOGÍA(S)'!I24) -> 0 | J24: =SUM(PACIENTES!J24+COMEDOR!J24+JORNADA!J24+'DIETOLOGÍA(S)'!J24) -> 0 | K24: =SUM(PACIENTES!K24+COMEDOR!K24+JORNADA!K24+'DIETOLOGÍA(S)'!K24) -> 0 | ... AH24: =SUM(PACIENTES!AH24+COMEDOR!AH24+JORNADA!AH24+'DIETOLOGÍA(S)'!AH24) -> 0 | AI24: =SUM(D24:AH24) -> 0
A25: 2212004023 | B25: TORONJA | C25: KG | D25: =SUM(PACIENTES!D25+COMEDOR!D25+JORNADA!D25+'DIETOLOGÍA(S)'!D25) -> 0 | E25: =SUM(PACIENTES!E25+COMEDOR!E25+JORNADA!E25+'DIETOLOGÍA(S)'!E25) -> 0 | F25: =SUM(PACIENTES!F25+COMEDOR!F25+JORNADA!F25+'DIETOLOGÍA(S)'!F25) -> 0 | G25: =SUM(PACIENTES!G25+COMEDOR!G25+JORNADA!G25+'DIETOLOGÍA(S)'!G25) -> 0 | H25: =SUM(PACIENTES!H25+COMEDOR!H25+JORNADA!H25+'DIETOLOGÍA(S)'!H25) -> 0 | I25: =SUM(PACIENTES!I25+COMEDOR!I25+JORNADA!I25+'DIETOLOGÍA(S)'!I25) -> 0 | J25: =SUM(PACIENTES!J25+COMEDOR!J25+JORNADA!J25+'DIETOLOGÍA(S)'!J25) -> 3 | K25: =SUM(PACIENTES!K25+COMEDOR!K25+JORNADA!K25+'DIETOLOGÍA(S)'!K25) -> 0 | ... AH25: =SUM(PACIENTES!AH25+COMEDOR!AH25+JORNADA!AH25+'DIETOLOGÍA(S)'!AH25) -> 0 | AI25: =SUM(D25:AH25) -> 12
A26: 2212004025 | B26: MANGO PETACON | C26: KG | D26: =SUM(PACIENTES!D26+COMEDOR!D26+JORNADA!D26+'DIETOLOGÍA(S)'!D26) -> 0 | E26: =SUM(PACIENTES!E26+COMEDOR!E26+JORNADA!E26+'DIETOLOGÍA(S)'!E26) -> 0 | F26: =SUM(PACIENTES!F26+COMEDOR!F26+JORNADA!F26+'DIETOLOGÍA(S)'!F26) -> 0 | G26: =SUM(PACIENTES!G26+COMEDOR!G26+JORNADA!G26+'DIETOLOGÍA(S)'!G26) -> 0 | H26: =SUM(PACIENTES!H26+COMEDOR!H26+JORNADA!H26+'DIETOLOGÍA(S)'!H26) -> 0 | I26: =SUM(PACIENTES!I26+COMEDOR!I26+JORNADA!I26+'DIETOLOGÍA(S)'!I26) -> 0 | J26: =SUM(PACIENTES!J26+COMEDOR!J26+JORNADA!J26+'DIETOLOGÍA(S)'!J26) -> 0 | K26: =SUM(PACIENTES!K26+COMEDOR!K26+JORNADA!K26+'DIETOLOGÍA(S)'!K26) -> 0 | ... AH26: =SUM(PACIENTES!AH26+COMEDOR!AH26+JORNADA!AH26+'DIETOLOGÍA(S)'!AH26) -> 0 | AI26: =SUM(D26:AH26) -> 0
A27: 2212004028 | B27: PLATANO DOMINICO | C27: KG | D27: =SUM(PACIENTES!D27+COMEDOR!D27+JORNADA!D27+'DIETOLOGÍA(S)'!D27) -> 0 | E27: =SUM(PACIENTES!E27+COMEDOR!E27+JORNADA!E27+'DIETOLOGÍA(S)'!E27) -> 0 | F27: =SUM(PACIENTES!F27+COMEDOR!F27+JORNADA!F27+'DIETOLOGÍA(S)'!F27) -> 0 | G27: =SUM(PACIENTES!G27+COMEDOR!G27+JORNADA!G27+'DIETOLOGÍA(S)'!G27) -> 0 | H27: =SUM(PACIENTES!H27+COMEDOR!H27+JORNADA!H27+'DIETOLOGÍA(S)'!H27) -> 0 | I27: =SUM(PACIENTES!I27+COMEDOR!I27+JORNADA!I27+'DIETOLOGÍA(S)'!I27) -> 2 | J27: =SUM(PACIENTES!J27+COMEDOR!J27+JORNADA!J27+'DIETOLOGÍA(S)'!J27) -> 1 | K27: =SUM(PACIENTES!K27+COMEDOR!K27+JORNADA!K27+'DIETOLOGÍA(S)'!K27) -> 0 | ... AH27: =SUM(PACIENTES!AH27+COMEDOR!AH27+JORNADA!AH27+'DIETOLOGÍA(S)'!AH27) -> 0 | AI27: =SUM(D27:AH27) -> 12
A28: 2212004029 | B28: UVA GLOBO | C28: KG | D28: =SUM(PACIENTES!D28+COMEDOR!D28+JORNADA!D28+'DIETOLOGÍA(S)'!D28) -> 0 | E28: =SUM(PACIENTES!E28+COMEDOR!E28+JORNADA!E28+'DIETOLOGÍA(S)'!E28) -> 0 | F28: =SUM(PACIENTES!F28+COMEDOR!F28+JORNADA!F28+'DIETOLOGÍA(S)'!F28) -> 0 | G28: =SUM(PACIENTES!G28+COMEDOR!G28+JORNADA!G28+'DIETOLOGÍA(S)'!G28) -> 30 | H28: =SUM(PACIENTES!H28+COMEDOR!H28+JORNADA!H28+'DIETOLOGÍA(S)'!H28) -> 0 | I28: =SUM(PACIENTES!I28+COMEDOR!I28+JORNADA!I28+'DIETOLOGÍA(S)'!I28) -> 28 | J28: =SUM(PACIENTES!J28+COMEDOR!J28+JORNADA!J28+'DIETOLOGÍA(S)'!J28) -> 28 | K28: =SUM(PACIENTES!K28+COMEDOR!K28+JORNADA!K28+'DIETOLOGÍA(S)'!K28) -> 0 | ... AH28: =SUM(PACIENTES!AH28+COMEDOR!AH28+JORNADA!AH28+'DIETOLOGÍA(S)'!AH28) -> 30 | AI28: =SUM(D28:AH28) -> 321
A29: 2212004030 | B29: UVA VERDE | C29: KG | D29: =SUM(PACIENTES!D29+COMEDOR!D29+JORNADA!D29+'DIETOLOGÍA(S)'!D29) -> 0 | E29: =SUM(PACIENTES!E29+COMEDOR!E29+JORNADA!E29+'DIETOLOGÍA(S)'!E29) -> 0 | F29: =SUM(PACIENTES!F29+COMEDOR!F29+JORNADA!F29+'DIETOLOGÍA(S)'!F29) -> 0 | G29: =SUM(PACIENTES!G29+COMEDOR!G29+JORNADA!G29+'DIETOLOGÍA(S)'!G29) -> 0 | H29: =SUM(PACIENTES!H29+COMEDOR!H29+JORNADA!H29+'DIETOLOGÍA(S)'!H29) -> 0 | I29: =SUM(PACIENTES!I29+COMEDOR!I29+JORNADA!I29+'DIETOLOGÍA(S)'!I29) -> 22 | J29: =SUM(PACIENTES!J29+COMEDOR!J29+JORNADA!J29+'DIETOLOGÍA(S)'!J29) -> 20 | K29: =SUM(PACIENTES!K29+COMEDOR!K29+JORNADA!K29+'DIETOLOGÍA(S)'!K29) -> 27 | ... AH29: =SUM(PACIENTES!AH29+COMEDOR!AH29+JORNADA!AH29+'DIETOLOGÍA(S)'!AH29) -> 0 | AI29: =SUM(D29:AH29) -> 223
A30: 2212004031 | B30: MANGO BARRANQUEÑO | C30: KG | D30: =SUM(PACIENTES!D30+COMEDOR!D30+JORNADA!D30+'DIETOLOGÍA(S)'!D30) -> 0 | E30: =SUM(PACIENTES!E30+COMEDOR!E30+JORNADA!E30+'DIETOLOGÍA(S)'!E30) -> 0 | F30: =SUM(PACIENTES!F30+COMEDOR!F30+JORNADA!F30+'DIETOLOGÍA(S)'!F30) -> 0 | G30: =SUM(PACIENTES!G30+COMEDOR!G30+JORNADA!G30+'DIETOLOGÍA(S)'!G30) -> 0 | H30: =SUM(PACIENTES!H30+COMEDOR!H30+JORNADA!H30+'DIETOLOGÍA(S)'!H30) -> 0 | I30: =SUM(PACIENTES!I30+COMEDOR!I30+JORNADA!I30+'DIETOLOGÍA(S)'!I30) -> 0 | J30: =SUM(PACIENTES!J30+COMEDOR!J30+JORNADA!J30+'DIETOLOGÍA(S)'!J30) -> 0 | K30: =SUM(PACIENTES!K30+COMEDOR!K30+JORNADA!K30+'DIETOLOGÍA(S)'!K30) -> 0 | ... AH30: =SUM(PACIENTES!AH30+COMEDOR!AH30+JORNADA!AH30+'DIETOLOGÍA(S)'!AH30) -> 0 | AI30: =SUM(D30:AH30) -> 0
A31: 2212004032 | B31: CIRUELA PASA SIN HUESO | C31: KG | D31: =SUM(PACIENTES!D31+COMEDOR!D31+JORNADA!D31+'DIETOLOGÍA(S)'!D31) -> 0 | E31: =SUM(PACIENTES!E31+COMEDOR!E31+JORNADA!E31+'DIETOLOGÍA(S)'!E31) -> 0 | F31: =SUM(PACIENTES!F31+COMEDOR!F31+JORNADA!F31+'DIETOLOGÍA(S)'!F31) -> 0 | G31: =SUM(PACIENTES!G31+COMEDOR!G31+JORNADA!G31+'DIETOLOGÍA(S)'!G31) -> 0 | H31: =SUM(PACIENTES!H31+COMEDOR!H31+JORNADA!H31+'DIETOLOGÍA(S)'!H31) -> 0 | I31: =SUM(PACIENTES!I31+COMEDOR!I31+JORNADA!I31+'DIETOLOGÍA(S)'!I31) -> 0 | J31: =SUM(PACIENTES!J31+COMEDOR!J31+JORNADA!J31+'DIETOLOGÍA(S)'!J31) -> 0 | K31: =SUM(PACIENTES!K31+COMEDOR!K31+JORNADA!K31+'DIETOLOGÍA(S)'!K31) -> 0 | ... AH31: =SUM(PACIENTES!AH31+COMEDOR!AH31+JORNADA!AH31+'DIETOLOGÍA(S)'!AH31) -> 0 | AI31: =SUM(D31:AH31) -> 2
A32: 2212004034 | B32: GRANADA ROJA | C32: KG | D32: =SUM(PACIENTES!D32+COMEDOR!D32+JORNADA!D32+'DIETOLOGÍA(S)'!D32) -> 0 | E32: =SUM(PACIENTES!E32+COMEDOR!E32+JORNADA!E32+'DIETOLOGÍA(S)'!E32) -> 0 | F32: =SUM(PACIENTES!F32+COMEDOR!F32+JORNADA!F32+'DIETOLOGÍA(S)'!F32) -> 0 | G32: =SUM(PACIENTES!G32+COMEDOR!G32+JORNADA!G32+'DIETOLOGÍA(S)'!G32) -> 0 | H32: =SUM(PACIENTES!H32+COMEDOR!H32+JORNADA!H32+'DIETOLOGÍA(S)'!H32) -> 0 | I32: =SUM(PACIENTES!I32+COMEDOR!I32+JORNADA!I32+'DIETOLOGÍA(S)'!I32) -> 0 | J32: =SUM(PACIENTES!J32+COMEDOR!J32+JORNADA!J32+'DIETOLOGÍA(S)'!J32) -> 0 | K32: =SUM(PACIENTES!K32+COMEDOR!K32+JORNADA!K32+'DIETOLOGÍA(S)'!K32) -> 0 | ... AH32: =SUM(PACIENTES!AH32+COMEDOR!AH32+JORNADA!AH32+'DIETOLOGÍA(S)'!AH32) -> 0 | AI32: =SUM(D32:AH32) -> 0
A33: 2212004035 | B33: TUNA | C33: KG | D33: =SUM(PACIENTES!D33+COMEDOR!D33+JORNADA!D33+'DIETOLOGÍA(S)'!D33) -> 0 | E33: =SUM(PACIENTES!E33+COMEDOR!E33+JORNADA!E33+'DIETOLOGÍA(S)'!E33) -> 0 | F33: =SUM(PACIENTES!F33+COMEDOR!F33+JORNADA!F33+'DIETOLOGÍA(S)'!F33) -> 0 | G33: =SUM(PACIENTES!G33+COMEDOR!G33+JORNADA!G33+'DIETOLOGÍA(S)'!G33) -> 0 | H33: =SUM(PACIENTES!H33+COMEDOR!H33+JORNADA!H33+'DIETOLOGÍA(S)'!H33) -> 0 | I33: =SUM(PACIENTES!I33+COMEDOR!I33+JORNADA!I33+'DIETOLOGÍA(S)'!I33) -> 0 | J33: =SUM(PACIENTES!J33+COMEDOR!J33+JORNADA!J33+'DIETOLOGÍA(S)'!J33) -> 2 | K33: =SUM(PACIENTES!K33+COMEDOR!K33+JORNADA!K33+'DIETOLOGÍA(S)'!K33) -> 0 | ... AH33: =SUM(PACIENTES!AH33+COMEDOR!AH33+JORNADA!AH33+'DIETOLOGÍA(S)'!AH33) -> 0 | AI33: =SUM(D33:AH33) -> 4
A34: 2212004038 | B34: GRANADA CHINA | C34: PIEZA | D34: =SUM(PACIENTES!D34+COMEDOR!D34+JORNADA!D34+'DIETOLOGÍA(S)'!D34) -> 0 | E34: =SUM(PACIENTES!E34+COMEDOR!E34+JORNADA!E34+'DIETOLOGÍA(S)'!E34) -> 0 | F34: =SUM(PACIENTES!F34+COMEDOR!F34+JORNADA!F34+'DIETOLOGÍA(S)'!F34) -> 0 | G34: =SUM(PACIENTES!G34+COMEDOR!G34+JORNADA!G34+'DIETOLOGÍA(S)'!G34) -> 0 | H34: =SUM(PACIENTES!H34+COMEDOR!H34+JORNADA!H34+'DIETOLOGÍA(S)'!H34) -> 0 | I34: =SUM(PACIENTES!I34+COMEDOR!I34+JORNADA!I34+'DIETOLOGÍA(S)'!I34) -> 0 | J34: =SUM(PACIENTES!J34+COMEDOR!J34+JORNADA!J34+'DIETOLOGÍA(S)'!J34) -> 0 | K34: =SUM(PACIENTES!K34+COMEDOR!K34+JORNADA!K34+'DIETOLOGÍA(S)'!K34) -> 0 | ... AH34: =SUM(PACIENTES!AH34+COMEDOR!AH34+JORNADA!AH34+'DIETOLOGÍA(S)'!AH34) -> 0 | AI34: =SUM(D34:AH34) -> 0
A35: GRUPO DE ALIMENTO: VERDURA
A36: 2212010003 | B36: CHILE JALAPEÑO | C36: KG | D36: =SUM(PACIENTES!D36+COMEDOR!D36+JORNADA!D36+'DIETOLOGÍA(S)'!D36) -> 0 | E36: =SUM(PACIENTES!E36+COMEDOR!E36+JORNADA!E36+'DIETOLOGÍA(S)'!E36) -> 0 | F36: =SUM(PACIENTES!F36+COMEDOR!F36+JORNADA!F36+'DIETOLOGÍA(S)'!F36) -> 0 | G36: =SUM(PACIENTES!G36+COMEDOR!G36+JORNADA!G36+'DIETOLOGÍA(S)'!G36) -> 0 | H36: =SUM(PACIENTES!H36+COMEDOR!H36+JORNADA!H36+'DIETOLOGÍA(S)'!H36) -> 0 | I36: =SUM(PACIENTES!I36+COMEDOR!I36+JORNADA!I36+'DIETOLOGÍA(S)'!I36) -> 1 | J36: =SUM(PACIENTES!J36+COMEDOR!J36+JORNADA!J36+'DIETOLOGÍA(S)'!J36) -> 0 | K36: =SUM(PACIENTES!K36+COMEDOR!K36+JORNADA!K36+'DIETOLOGÍA(S)'!K36) -> 0 | ... AH36: =SUM(PACIENTES!AH36+COMEDOR!AH36+JORNADA!AH36+'DIETOLOGÍA(S)'!AH36) -> 0 | AI36: =SUM(D36:AH36) -> 3
A37: 2212010004 | B37: CHAMPIÑONES | C37: KG | D37: =SUM(PACIENTES!D37+COMEDOR!D37+JORNADA!D37+'DIETOLOGÍA(S)'!D37) -> 0 | E37: =SUM(PACIENTES!E37+COMEDOR!E37+JORNADA!E37+'DIETOLOGÍA(S)'!E37) -> 40 | F37: =SUM(PACIENTES!F37+COMEDOR!F37+JORNADA!F37+'DIETOLOGÍA(S)'!F37) -> 0 | G37: =SUM(PACIENTES!G37+COMEDOR!G37+JORNADA!G37+'DIETOLOGÍA(S)'!G37) -> 0 | H37: =SUM(PACIENTES!H37+COMEDOR!H37+JORNADA!H37+'DIETOLOGÍA(S)'!H37) -> 18 | I37: =SUM(PACIENTES!I37+COMEDOR!I37+JORNADA!I37+'DIETOLOGÍA(S)'!I37) -> 1 | J37: =SUM(PACIENTES!J37+COMEDOR!J37+JORNADA!J37+'DIETOLOGÍA(S)'!J37) -> 1 | K37: =SUM(PACIENTES!K37+COMEDOR!K37+JORNADA!K37+'DIETOLOGÍA(S)'!K37) -> 0 | ... AH37: =SUM(PACIENTES!AH37+COMEDOR!AH37+JORNADA!AH37+'DIETOLOGÍA(S)'!AH37) -> 0 | AI37: =SUM(D37:AH37) -> 85
A38: 2212010005 | B38: TE DE LIMON | C38: MANOJO | D38: =SUM(PACIENTES!D38+COMEDOR!D38+JORNADA!D38+'DIETOLOGÍA(S)'!D38) -> 0 | E38: =SUM(PACIENTES!E38+COMEDOR!E38+JORNADA!E38+'DIETOLOGÍA(S)'!E38) -> 2 | F38: =SUM(PACIENTES!F38+COMEDOR!F38+JORNADA!F38+'DIETOLOGÍA(S)'!F38) -> 2 | G38: =SUM(PACIENTES!G38+COMEDOR!G38+JORNADA!G38+'DIETOLOGÍA(S)'!G38) -> 2 | H38: =SUM(PACIENTES!H38+COMEDOR!H38+JORNADA!H38+'DIETOLOGÍA(S)'!H38) -> 0 | I38: =SUM(PACIENTES!I38+COMEDOR!I38+JORNADA!I38+'DIETOLOGÍA(S)'!I38) -> 2 | J38: =SUM(PACIENTES!J38+COMEDOR!J38+JORNADA!J38+'DIETOLOGÍA(S)'!J38) -> 0 | K38: =SUM(PACIENTES!K38+COMEDOR!K38+JORNADA!K38+'DIETOLOGÍA(S)'!K38) -> 2 | ... AH38: =SUM(PACIENTES!AH38+COMEDOR!AH38+JORNADA!AH38+'DIETOLOGÍA(S)'!AH38) -> 0 | AI38: =SUM(D38:AH38) -> 26
A39: 2212010006 | B39: TOMILLO FRESCO | C39: MANOJO | D39: =SUM(PACIENTES!D39+COMEDOR!D39+JORNADA!D39+'DIETOLOGÍA(S)'!D39) -> 0 | E39: =SUM(PACIENTES!E39+COMEDOR!E39+JORNADA!E39+'DIETOLOGÍA(S)'!E39) -> 0 | F39: =SUM(PACIENTES!F39+COMEDOR!F39+JORNADA!F39+'DIETOLOGÍA(S)'!F39) -> 0 | G39: =SUM(PACIENTES!G39+COMEDOR!G39+JORNADA!G39+'DIETOLOGÍA(S)'!G39) -> 0 | H39: =SUM(PACIENTES!H39+COMEDOR!H39+JORNADA!H39+'DIETOLOGÍA(S)'!H39) -> 0 | I39: =SUM(PACIENTES!I39+COMEDOR!I39+JORNADA!I39+'DIETOLOGÍA(S)'!I39) -> 0 | J39: =SUM(PACIENTES!J39+COMEDOR!J39+JORNADA!J39+'DIETOLOGÍA(S)'!J39) -> 0 | K39: =SUM(PACIENTES!K39+COMEDOR!K39+JORNADA!K39+'DIETOLOGÍA(S)'!K39) -> 0 | ... AH39: =SUM(PACIENTES!AH39+COMEDOR!AH39+JORNADA!AH39+'DIETOLOGÍA(S)'!AH39) -> 0 | AI39: =SUM(D39:AH39) -> 0
A40: 2212010007 | B40: ACELGA | C40: MANOJO | D40: =SUM(PACIENTES!D40+COMEDOR!D40+JORNADA!D40+'DIETOLOGÍA(S)'!D40) -> 0 | E40: =SUM(PACIENTES!E40+COMEDOR!E40+JORNADA!E40+'DIETOLOGÍA(S)'!E40) -> 0 | F40: =SUM(PACIENTES!F40+COMEDOR!F40+JORNADA!F40+'DIETOLOGÍA(S)'!F40) -> 0 | G40: =SUM(PACIENTES!G40+COMEDOR!G40+JORNADA!G40+'DIETOLOGÍA(S)'!G40) -> 0 | H40: =SUM(PACIENTES!H40+COMEDOR!H40+JORNADA!H40+'DIETOLOGÍA(S)'!H40) -> 0 | I40: =SUM(PACIENTES!I40+COMEDOR!I40+JORNADA!I40+'DIETOLOGÍA(S)'!I40) -> 0 | J40: =SUM(PACIENTES!J40+COMEDOR!J40+JORNADA!J40+'DIETOLOGÍA(S)'!J40) -> 1 | K40: =SUM(PACIENTES!K40+COMEDOR!K40+JORNADA!K40+'DIETOLOGÍA(S)'!K40) -> 0 | ... AH40: =SUM(PACIENTES!AH40+COMEDOR!AH40+JORNADA!AH40+'DIETOLOGÍA(S)'!AH40) -> 0 | AI40: =SUM(D40:AH40) -> 4
A41: 2212010008 | B41: AGUACATE | C41: KG | D41: =SUM(PACIENTES!D41+COMEDOR!D41+JORNADA!D41+'DIETOLOGÍA(S)'!D41) -> 25 | E41: =SUM(PACIENTES!E41+COMEDOR!E41+JORNADA!E41+'DIETOLOGÍA(S)'!E41) -> 0 | F41: =SUM(PACIENTES!F41+COMEDOR!F41+JORNADA!F41+'DIETOLOGÍA(S)'!F41) -> 10 | G41: =SUM(PACIENTES!G41+COMEDOR!G41+JORNADA!G41+'DIETOLOGÍA(S)'!G41) -> 10 | H41: =SUM(PACIENTES!H41+COMEDOR!H41+JORNADA!H41+'DIETOLOGÍA(S)'!H41) -> 0 | I41: =SUM(PACIENTES!I41+COMEDOR!I41+JORNADA!I41+'DIETOLOGÍA(S)'!I41) -> 13 | J41: =SUM(PACIENTES!J41+COMEDOR!J41+JORNADA!J41+'DIETOLOGÍA(S)'!J41) -> 2 | K41: =SUM(PACIENTES!K41+COMEDOR!K41+JORNADA!K41+'DIETOLOGÍA(S)'!K41) -> 0 | ... AH41: =SUM(PACIENTES!AH41+COMEDOR!AH41+JORNADA!AH41+'DIETOLOGÍA(S)'!AH41) -> 0 | AI41: =SUM(D41:AH41) -> 172
...

Sheet RECEPCIÓN
B1: DESCRIPCIÓN | C1: UNIDAD DE MEDIDA | D1: 1 | E1: 2 | F1: 3 | G1: 4 | H1: 5 | I1: 6 | J1: 7 | K1: 8 | L1: 9 | M1: 10 | N1: 11 | O1: 12 | P1: 13 | Q1: 14 | R1: 15 | S1: 16 | T1: 17 | U1: 18 | V1: 19 | W1: 20 | X1: 21 | Y1: 22 | Z1: 23 | AA1: 24 | AB1: 25 | AC1: 26 | AD1: 27 | AE1: 28 | AF1: 29 | AG1: 30 | AH1: 31 | AI1: TOTAL
A3: GRUPO DE ALIMENTO: FRUTA
A4: 2212004001 | B4: CIRUELA ROJA | C4: KG | AI4: =SUM(D4:AH4) -> 0
A5: 2212004002 | B5: CAÑA DE AZUCAR | C5: PIEZA | AI5: =SUM(D5:AH5) -> 0
A6: 2212004003 | B6: CIRUELA AMARILLA | C6: KG | AI6: =SUM(D6:AH6) -> 0
A7: 2212004004 | B7: DURAZNO | C7: KG | AI7: =SUM(D7:AH7) -> 0
A8: 2212004005 | B8: FRESA | C8: KG | AI8: =SUM(D8:AH8) -> 0
A9: 2212004006 | B9: GUAYABA | C9: KG | AI9: =SUM(D9:AH9) -> 0
A10: 2212004007 | B10: JICAMA | C10: KG | AI10: =SUM(D10:AH10) -> 0
A11: 2212004008 | B11: LIMA | C11: KG | AI11: =SUM(D11:AH11) -> 0
A12: 2212004009 | B12: MANDARINA | C12: KG | AI12: =SUM(D12:AH12) -> 0
A13: 2212004011 | B13: MANZANA DELICIA | C13: KG | AI13: =SUM(D13:AH13) -> 0
A14: 2212004012 | B14: MANZANA GOLDEN | C14: KG | AI14: =SUM(D14:AH14) -> 0
A15: 2212004013 | B15: MELON CANTALUP | C15: KG | AI15: =SUM(D15:AH15) -> 0
... A34: 2212004038 | B34: GRANADA CHINA | C34: PIEZA | AI34: =SUM(D34:AH34) -> 0
A35: GRUPO DE ALIMENTO: VERDURA
A36: 2212010003 | B36: CHILE JALAPEÑO | C36: KG | AI36: =SUM(D36:AH36) -> 0
A37: 2212010004 | B37: CHAMPIÑONES | C37: KG | AI37: =SUM(D37:AH37) -> 0
A38: 2212010005 | B38: TE DE LIMON | C38: MANOJO | AI38: =SUM(D38:AH38) -> 0
A39: 2212010006 | B39: TOMILLO FRESCO | C39: MANOJO | AI39: =SUM(D39:AH39) -> 0
A40: 2212010007 | B40: ACELGA | C40: MANOJO | AI40: =SUM(D40:AH40) -> 0
A41: 2212010008 | B41: AGUACATE | C41: KG | AI41: =SUM(D41:AH41) -> 0
A42: 2212010009 | B42: APIO | C42: KG | AI42: =SUM(D42:AH42) -> 0
A43: 2212010010 | B43: BETABEL | C43: MANOJO | AI43: =SUM(D43:AH43) -> 0
A44: 2212010011 | B44: BROCOLI | C44: KG | AI44: =SUM(D44:AH44) -> 0
A45: 2212010012 | B45: CALABACITA ITALIANA | C45: KG | AI45: =SUM(D45:AH45) -> 0
A46: 2212010013 | B46: CALABAZA DURA | C46: KG | AI46: =SUM(D46:AH46) -> 0
A47: 2212010014 | B47: CAMOTE AMARILLO | C47: KG | AI47: =SUM(D47:AH47) -> 0
... A89: 2212004040 | B89: RABANO CHAMPION SIN RABO | C89: KG | AI89: =SUM(D89:AH89) -> 0
A90: GRUPO DE ALIMENTO: CERDO
A91: 2212002001 | B91: FAJITAS DE CERDO | C91: KG | AI91: =SUM(D91:AH91) -> 0
A92: 2212002004 | B92: CARNAZA DE CERDO EN TROZO | C92: KG | AI92: =SUM(D92:AH92) -> 0
A93: 2212002007 | B93: CARNE MOLIDA DE CERDO POCA GRASA | C93: KG | AI93: =SUM(D93:AH93) -> 0
A94: 2212002009 | B94: CHAMORRO DE CERDO PARTIDO | C94: KG | AI94: =SUM(D94:AH94) -> 0
A95: 2212002010 | B95: CHULETA DE CERDO AHUMADA CORTE DE 120GR C/U | C95: KG | AI95: =SUM(D95:AH95) -> 0
A96: 2212002011 | B96: COSTILLA DE CERDO EN TROCITO | C96: KG | AI96: =SUM(D96:AH96) -> 0
A97: 2212002014 | B97: LOMO DE CERDO | C97: KG | AI97: =SUM(D97:AH97) -> 0
A98: 2212002016 | B98: MILANESA DE CERDO | C98: KG | AI98: =SUM(D98:AH98) -> 0
A99: 2212002018 | B99: PIERNA DE CERDO EN TROZO CORTE DE 3 KILOS | C99: KG | AI99: =SUM(D99:AH99) -> 0
A100: 2212002022 | B100: PIERNA DE CERDO EN TROCITO | C100: KG | AI100: =SUM(D100:AH100) -> 0
...

Sheet PACIENTES
A1: CÓDIGO | B1: DESCRIPCIÓN | C1: UNIDAD DE MEDIDA | D1: 1 | E1: 2 | F1: 3 | G1: 4 | H1: 5 | I1: 6 | J1: 7 | K1: 8 | L1: 9 | M1: 10 | N1: 11 | O1: 12 | P1: 13 | Q1: 14 | R1: 15 | S1: 16 | T1: 17 | U1: 18 | V1: 19 | W1: 20 | X1: 21 | Y1: 22 | Z1: 23 | AA1: 24 | AB1: 25 | AC1: 26 | AD1: 27 | AE1: 28 | AF1: 29 | AG1: 30 | AH1: 31 | AI1: TOTAL
A3: GRUPO DE ALIMENTO: FRUTA
A4: 2212004001 | B4: CIRUELA ROJA | C4: KG | D4: 0 | E4: 0 | F4: 0 | G4: 0 | H4: 0 | I4: 0 | J4: 0 | K4: 0 | L4: 0 | M4: 0 | N4: 0 | O4: 0 | P4: 0 | Q4: 0 | R4: 0 | S4: 0 | T4: 0 | U4: 0 | V4: 0 | W4: 0 | X4: 0 | Y4: 0 | Z4: 0 | AA4: 0 | AB4: 0 | AC4: 0 | AD4: 0 | AE4: 0 | AF4: 0 | AG4: 0 | AH4: 0 | AI4: =SUM(D4:AH4) -> 0
A5: 2212004002 | B5: CAÑA DE AZUCAR | C5: PIEZA | D5: 0 | E5: 0 | F5: 0 | G5: 0 | H5: 0 | I5: 0 | J5: 0 | K5: 0 | L5: 0 | M5: 0 | N5: 0 | O5: 0 | P5: 0 | Q5: 0 | R5: 0 | S5: 0 | T5: 0 | U5: 0 | V5: 0 | W5: 0 | X5: 0 | Y5: 0 | Z5: 0 | AA5: 0 | AB5: 0 | AC5: 0 | AD5: 0 | AE5: 0 | AF5: 0 | AG5: 0 | AH5: 0 | AI5: =SUM(D5:AH5) -> 0
A6: 2212004003 | B6: CIRUELA AMARILLA | C6: KG | D6: 0 | E6: 0 | F6: 0 | G6: 0 | H6: 0 | I6: 0 | J6: 0 | K6: 0 | L6: 0 | M6: 0 | N6: 0 | O6: 0 | P6: 0 | Q6: 0 | R6: 0 | S6: 0 | T6: 0 | U6: 0 | V6: 0 | W6: 0 | X6: 0 | Y6: 0 | Z6: 0 | AA6: 0 | AB6: 0 | AC6: 0 | AD6: 0 | AE6: 0 | AF6: 0 | AG6: 0 | AH6: 0 | AI6: =SUM(D6:AH6) -> 0
A7: 2212004004 | B7: DURAZNO | C7: KG | D7: 0 | E7: 30 | F7: 0 | G7: 0 | H7: 0 | I7: 0 | J7: 0 | K7: 0 | L7: 0 | M7: 0 | N7: 0 | O7: 0 | P7: 30 | Q7: 0 | R7: 0 | S7: 0 | T7: 0 | U7: 0 | V7: 0 | W7: 0 | X7: 0 | Y7: 0 | Z7: 0 | AA7: 0 | AB7: 0 | AC7: 30 | AD7: 0 | AE7: 30 | AF7: 0 | AG7: 0 | AH7: 0 | AI7: =SUM(D7:AH7) -> 120
A8: 2212004005 | B8: FRESA | C8: KG | D8: 0 | E8: 0 | F8: 0 | G8: 0 | H8: 0 | I8: 0 | J8: 0 | K8: 0 | L8: 0 | M8: 0 | N8: 0 | O8: 0 | P8: 0 | Q8: 0 | R8: 0 | S8: 0 | T8: 0 | U8: 0 | V8: 0 | W8: 0 | X8: 0 | Y8: 0 | Z8: 0 | AA8: 0 | AB8: 0 | AC8: 0 | AD8: 0 | AE8: 0 | AF8: 0 | AG8: 0 | AH8: 0 | AI8: =SUM(D8:AH8) -> 0
A9: 2212004006 | B9: GUAYABA | C9: KG | D9: 0 | E9: 30 | F9: 0 | G9: 0 | H9: 30 | I9: 0 | J9: 0 | K9: 0 | L9: 30 | M9: 0 | N9: 0 | O9: 0 | P9: 30 | Q9: 0 | R9: 0 | S9: 0 | T9: 0 | U9: 0 | V9: 0 | W9: 30 | X9: 0 | Y9: 0 | Z9: 0 | AA9: 0 | AB9: 0 | AC9: 30 | AD9: 30 | AE9: 30 | AF9: 0 | AG9: 0 | AH9: 0 | AI9: =SUM(D9:AH9) -> 240
A10: 2212004007 | B10: JICAMA | C10: KG | D10: 0 | E10: 0 | F10: 0 | G10: 0 | H10: 0 | I10: 0 | J10: 0 | K10: 0 | L10: 0 | M10: 0 | N10: 0 | O10: 0 | P10: 0 | Q10: 0 | R10: 0 | S10: 0 | T10: 0 | U10: 0 | V10: 0 | W10: 0 | X10: 0 | Y10: 0 | Z10: 0 | AA10: 0 | AB10: 0 | AC10: 0 | AD10: 0 | AE10: 0 | AF10: 0 | AG10: 0 | AH10: 0 | AI10: =SUM(D10:AH10) -> 0
A11: 2212004008 | B11: LIMA | C11: KG | D11: 0 | E11: 0 | F11: 0 | G11: 0 | H11: 0 | I11: 0 | J11: 0 | K11: 0 | L11: 0 | M11: 0 | N11: 0 | O11: 0 | P11: 0 | Q11: 0 | R11: 0 | S11: 0 | T11: 0 | U11: 0 | V11: 0 | W11: 0 | X11: 0 | Y11: 0 | Z11: 0 | AA11: 0 | AB11: 0 | AC11: 0 | AD11: 0 | AE11: 0 | AF11: 0 | AG11: 0 | AH11: 0 | AI11: =SUM(D11:AH11) -> 0
A12: 2212004009 | B12: MANDARINA | C12: KG | D12: 0 | E12: 0 | F12: 0 | G12: 0 | H12: 0 | I12: 0 | J12: 0 | K12: 0 | L12: 0 | M12: 0 | N12: 0 | O12: 0 | P12: 0 | Q12: 0 | R12: 0 | S12: 0 | T12: 0 | U12: 0 | V12: 0 | W12: 0 | X12: 0 | Y12: 0 | Z12: 0 | AA12: 0 | AB12: 0 | AC12: 0 | AD12: 0 | AE12: 0 | AF12: 0 | AG12: 0 | AH12: 0 | AI12: =SUM(D12:AH12) -> 0
A13: 2212004011 | B13: MANZANA DELICIA | C13: KG | D13: 23 | E13: 8 | F13: 0 | G13: 0 | H13: 15 | I13: 0 | J13: 0 | K13: 45 | L13: 15 | M13: 0 | N13: 0 | O13: 0 | P13: 8 | Q13: 45 | R13: 36 | S13: 23 | T13: 0 | U13: 0 | V13: 45 | W13: 15 | X13: 0 | Y13: 0 | Z13: 45 | AA13: 0 | AB13: 0 | AC13: 8 | AD13: 0 | AE13: 8 | AF13: 45 | AG13: 36 | AH13: 0 | AI13: =SUM(D13:AH13) -> 420
A14: 2212004012 | B14: MANZANA GOLDEN | C14: KG | D14: 15 | E14: 15 | F14: 0 | G14: 0 | H14: 15 | I14: 60 | J14: 60 | K14: 15 | L14: 15 | M14: 0 | N14: 0 | O14: 0 | P14: 30 | Q14: 15 | R14: 75 | S14: 15 | T14: 0 | U14: 0 | V14: 15 | W14: 15 | X14: 60 | Y14: 60 | Z14: 15 | AA14: 0 | AB14: 0 | AC14: 30 | AD14: 60 | AE14: 30 | AF14: 15 | AG14: 75 | AH14: 0 | AI14: =SUM(D14:AH14) -> 705
A15: 2212004013 | B15: MELON CANTALUP | C15: KG | D15: 50 | E15: 0 | F15: 0 | G15: 0 | H15: 50 | I15: 0 | J15: 0 | K15: 0 | L15: 50 | M15: 0 | N15: 0 | O15: 0 | P15: 0 | Q15: 0 | R15: 0 | S15: 50 | T15: 0 | U15: 0 | V15: 0 | W15: 50 | X15: 0 | Y15: 0 | Z15: 0 | AA15: 0 | AB15: 0 | AC15: 0 | AD15: 0 | AE15: 0 | AF15: 0 | AG15: 0 | AH15: 0 | AI15: =SUM(D15:AH15) -> 250
... A89: 2212004040 | B89: RABANO CHAMPION SIN RABO | C89: KG | D89: 0 | E89: 0 | F89: 0 | G89: 0 | H89: 0 | I89: 0 | J89: 0 | K89: 0 | L89: 0 | M89: 0 | N89: 0 | O89: 0 | P89: 0 | Q89: 0 | R89: 0 | S89: 0 | T89: 0 | U89: 0 | V89: 0 | W89: 0 | X89: 0 | Y89: 0 | Z89: 0 | AA89: 0 | AB89: 0 | AC89: 0 | AD89: 0 | AE89: 0 | AF89: 0 | AG89: 0 | AH89: 0 | AI89: =SUM(D89:AH89) -> 0
A90: GRUPO DE ALIMENTO: CERDO
A91: 2212002001 | B91: FAJITAS DE CERDO | C91: KG | D91: 0 | E91: 0 | F91: 0 | G91: 0 | H91: 0 | I91: 0 | J91: 0 | K91: 0 | L91: 0 | M91: 0 | N91: 0 | O91: 0 | P91: 0 | Q91: 0 | R91: 0 | S91: 0 | T91: 0 | U91: 0 | V91: 0 | W91: 0 | X91: 0 | Y91: 0 | Z91: 0 | AA91: 0 | AB91: 0 | AC91: 0 | AD91: 0 | AE91: 0 | AF91: 0 | AG91: 0 | AH91: 0 | AI91: =SUM(D91:AH91) -> 0
A92: 2212002004 | B92: CARNAZA DE CERDO EN TROZO | C92: KG | D92: 0 | E92: 0 | F92: 0 | G92: 0 | H92: 0 | I92: 0 | J92: 0 | K92: 0 | L92: 0 | M92: 0 | N92: 0 | O92: 0 | P92: 0 | Q92: 0 | R92: 0 | S92: 0 | T92: 0 | U92: 0 | V92: 0 | W92: 0 | X92: 0 | Y92: 0 | Z92: 0 | AA92: 0 | AB92: 0 | AC92: 0 | AD92: 0 | AE92: 0 | AF92: 0 | AG92: 0 | AH92: 0 | AI92: =SUM(D92:AH92) -> 0
A93: 2212002007 | B93: CARNE MOLIDA DE CERDO POCA GRASA | C93: KG | D93: 0 | E93: 0 | F93: 0 | G93: 0 | H93: 0 | I93: 0 | J93: 0 | K93: 0 | L93: 0 | M93: 0 | N93: 0 | O93: 0 | P93: 0 | Q93: 0 | R93: 0 | S93: 0 | T93: 0 | U93: 0 | V93: 0 | W93: 0 | X93: 0 | Y93: 0 | Z93: 0 | AA93: 0 | AB93: 0 | AC93: 0 | AD93: 0 | AE93: 0 | AF93: 0 | AG93: 0 | AH93: 0 | AI93: =SUM(D93:AH93) -> 0
A94: 2212002009 | B94: CHAMORRO DE CERDO PARTIDO | C94: KG | D94: 0 | E94: 0 | F94: 0 | G94: 0 | H94: 0 | I94: 0 | J94: 0 | K94: 0 | L94: 0 | M94: 0 | N94: 0 | O94: 0 | P94: 0 | Q94: 0 | R94: 0 | S94: 0 | T94: 0 | U94: 0 | V94: 0 | W94: 0 | X94: 0 | Y94: 0 | Z94: 0 | AA94: 0 | AB94: 0 | AC94: 0 | AD94: 0 | AE94: 0 | AF94: 0 | AG94: 0 | AH94: 0 | AI94: =SUM(D94:AH94) -> 0
A95: 2212002010 | B95: CHULETA DE CERDO AHUMADA CORTE DE 120GR C/U | C95: KG | D95: 0 | E95: 0 | F95: 0 | G95: 0 | H95: 0 | I95: 0 | J95: 0 | K95: 0 | L95: 0 | M95: 0 | N95: 0 | O95: 0 | P95: 0 | Q95: 0 | R95: 0 | S95: 0 | T95: 0 | U95: 0 | V95: 0 | W95: 0 | X95: 0 | Y95: 0 | Z95: 0 | AA95: 0 | AB95: 0 | AC95: 0 | AD95: 0 | AE95: 0 | AF95: 0 | AG95: 0 | AH95: 0 | AI95: =SUM(D95:AH95) -> 0
A96: 2212002011 | B96: COSTILLA DE CERDO EN TROCITO | C96: KG | D96: 0 | E96: 0 | F96: 0 | G96: 0 | H96: 0 | I96: 0 | J96: 0 | K96: 0 | L96: 0 | M96: 0 | N96: 0 | O96: 0 | P96: 0 | Q96: 0 | R96: 0 | S96: 0 | T96: 0 | U96: 0 | V96: 0 | W96: 0 | X96: 0 | Y96: 0 | Z96: 0 | AA96: 0 | AB96: 0 | AC96: 0 | AD96: 0 | AE96: 0 | AF96: 0 | AG96: 0 | AH96: 0 | AI96: =SUM(D96:AH96) -> 0
A97: 2212002014 | B97: LOMO DE CERDO | C97: KG | D97: 0 | E97: 0 | F97: 0 | G97: 0 | H97: 0 | I97: 0 | J97: 0 | K97: 0 | L97: 0 | M97: 0 | N97: 0 | O97: 0 | P97: 0 | Q97: 0 | R97: 0 | S97: 0 | T97: 0 | U97: 0 | V97: 0 | W97: 0 | X97: 0 | Y97: 0 | Z97: 0 | AA97: 0 | AB97: 0 | AC97: 0 | AD97: 0 | AE97: 0 | AF97: 0 | AG97: 0 | AH97: 0 | AI97: =SUM(D97:AH97) -> 0
A98: 2212002016 | B98: MILANESA DE CERDO | C98: KG | D98: 0 | E98: 0 | F98: 0 | G98: 0 | H98: 0 | I98: 0 | J98: 0 | K98: 0 | L98: 0 | M98: 0 | N98: 0 | O98: 0 | P98: 0 | Q98: 0 | R98: 0 | S98: 0 | T98: 0 | U98: 0 | V98: 0 | W98: 0 | X98: 0 | Y98: 0 | Z98: 0 | AA98: 0 | AB98: 0 | AC98: 0 | AD98: 0 | AE98: 0 | AF98: 0 | AG98: 0 | AH98: 0 | AI98: =SUM(D98:AH98) -> 0
A99: 2212002018 | B99: PIERNA DE CERDO EN TROZO CORTE DE 3 KILOS | C99: KG | D99: 0 | E99: 0 | F99: 0 | G99: 0 | H99: 0 | I99: 0 | J99: 0 | K99: 0 | L99: 0 | M99: 0 | N99: 0 | O99: 0 | P99: 0 | Q99: 0 | R99: 0 | S99: 0 | T99: 0 | U99: 0 | V99: 0 | W99: 0 | X99: 0 | Y99: 0 | Z99: 0 | AA99: 0 | AB99: 0 | AC99: 0 | AD99: 0 | AE99: 0 | AF99: 0 | AG99: 0 | AH99: 0 | AI99: =SUM(D99:AH99) -> 0
A100: 2212002022 | B100: PIERNA DE CERDO EN TROCITO | C100: KG | D100: 0 | E100: 0 | F100: 0 | G100: 0 | H100: 0 | I100: 0 | J100: 0 | K100: 0 | L100: 0 | M100: 0 | N100: 0 | O100: 0 | P100: 0 | Q100: 0 | R100: 0 | S100: 0 | T100: 0 | U100: 0 | V100: 0 | W100: 0 | X100: 0 | Y100: 0 | Z100: 0 | AA100: 0 | AB100: 0 | AC100: 0 | AD100: 0 | AE100: 0 | AF100: 0 | AG100: 0 | AH100: 0 | AI100: =SUM(D100:AH100) -> 0
A101: 2212002023 | B101: CARNITAS | C101: KG | D101: 0 | E101: 0 | F101: 0 | G101: 0 | H101: 0 | I101: 0 | J101: 0 | K101: 0 | L101: 0 | M101: 0 | N101: 0 | O101: 0 | P101: 0 | Q101: 0 | R101: 0 | S101: 0 | T101: 0 | U101: 0 | V101: 0 | W101: 0 | X101: 0 | Y101: 0 | Z101: 0 | AA101: 0 | AB101: 0 | AC101: 0 | AD101: 0 | AE101: 0 | AF101: 0 | AG101: 0 | AH101: 0 | AI101: =SUM(D101:AH101) -> 0
A102: 2212002025 | B102: CABEZA DE CERDO PARTIDA | C102: KG | D102: 0 | E102: 0 | F102: 0 | G102: 0 | H102: 0 | I102: 0 | J102: 0 | K102: 0 | L102: 0 | M102: 0 | N102: 0 | O102: 0 | P102: 0 | Q102: 0 | R102: 0 | S102: 0 | T102: 0 | U102: 0 | V102: 0 | W102: 0 | X102: 0 | Y102: 0 | Z102: 0 | AA102: 0 | AB102: 0 | AC102: 0 | AD102: 0 | AE102: 0 | AF102: 0 | AG102: 0 | AH102: 0 | AI102: =SUM(D102:AH102) -> 0
... A111: 2212002046 | B111: LOMO MECHADO | C111: KG | D111: 0 | E111: 0 | F111: 0 | G111: 0 | H111: 0 | I111: 0 | J111: 0 | K111: 0 | L111: 0 | M111: 0 | N111: 0 | O111: 0 | P111: 0 | Q111: 0 | R111: 0 | S111: 0 | T111: 0 | U111: 0 | V111: 0 | W111: 0 | X111: 0 | Y111: 0 | Z111: 0 | AA111: 0 | AB111: 0 | AC111: 0 | AD111: 0 | AE111: 0 | AF111: 0 | AG111: 0 | AH111: 0 | AI111: =SUM(D111:AH111) -> 0
A112: GRUPO DE ALIMENTO: RES
A113: 2212002003 | B113: BISTECK DE RES AGUAYON PARA BROCHETA | C113: KG | D113: 0 | E113: 0 | F113: 0 | G113: 0 | H113: 0 | I113: 0 | J113: 0 | K113: 0 | L113: 0 | M113: 0 | N113: 0 | O113: 0 | P113: 85 | Q113: 0 | R113: 0 | S113: 0 | T113: 0 | U113: 0 | V113: 0 | W113: 0 | X113: 0 | Y113: 0 | Z113: 0 | AA113: 0 | AB113: 0 | AC113: 0 | AD113: 0 | AE113: 85 | AF113: 0 | AG113: 0 | AH113: 0 | AI113: =SUM(D113:AH113) -> 170
A114: 2212002005 | B114: CARNE DE RES PARA COCIDO CON PLATANO Y POCO HUESO | C114: KG | D114: 0 | E114: 0 | F114: 0 | G114: 0 | H114: 0 | I114: 0 | J114: 0 | K114: 0 | L114: 0 | M114: 0 | N114: 0 | O114: 0 | P114: 0 | Q114: 0 | R114: 0 | S114: 0 | T114: 0 | U114: 0 | V114: 0 | W114: 0 | X114: 0 | Y114: 0 | Z114: 0 | AA114: 0 | AB114: 0 | AC114: 55 | AD114: 0 | AE114: 0 | AF114: 0 | AG114: 0 | AH114: 0 | AI114: =SUM(D114:AH114) -> 55
A115: 2212002006 | B115: CARNE DE RES PARA DESHEBRAR CORTE DE KILO | C115: KG | D115: 0 | E115: 0 | F115: 0 | G115: 0 | H115: 0 | I115: 0 | J115: 0 | K115: 0 | L115: 0 | M115: 0 | N115: 0 | O115: 0 | P115: 0 | Q115: 0 | R115: 0 | S115: 0 | T115: 0 | U115: 0 | V115: 0 | W115: 0 | X115: 0 | Y115: 0 | Z115: 0 | AA115: 0 | AB115: 0 | AC115: 0 | AD115: 0 | AE115: 0 | AF115: 0 | AG115: 0 | AH115: 0 | AI115: =SUM(D115:AH115) -> 0
A116: 2212002008 | B116: CARNE MOLIDA DE RES POCA GRASA | C116: KG | D116: 0 | E116: 0 | F116: 0 | G116: 0 | H116: 0 | I116: 0 | J116: 0 | K116: 0 | L116: 0 | M116: 0 | N116: 0 | O116: 0 | P116: 0 | Q116: 0 | R116: 0 | S116: 0 | T116: 0 | U116: 0 | V116: 55 | W116: 0 | X116: 0 | Y116: 0 | Z116: 0 | AA116: 0 | AB116: 0 | AC116: 0 | AD116: 0 | AE116: 0 | AF116: 0 | AG116: 0 | AH116: 0 | AI116: =SUM(D116:AH116) -> 55
A117: 2212002012 | B117: CUETE DE RES EN TROCITO | C117: KG | D117: 0 | E117: 75 | F117: 0 | G117: 0 | H117: 0 | I117: 0 | J117: 0 | K117: 0 | L117: 0 | M117: 0 | N117: 0 | O117: 0 | P117: 0 | Q117: 0 | R117: 0 | S117: 0 | T117: 0 | U117: 0 | V117: 0 | W117: 0 | X117: 0 | Y117: 0 | Z117: 0 | AA117: 0 | AB117: 0 | AC117: 0 | AD117: 0 | AE117: 0 | AF117: 0 | AG117: 0 | AH117: 0 | AI117: =SUM(D117:AH117) -> 75
A118: 2212002013 | B118: FAJITAS DE RES | C118: KG | D118: 0 | E118: 0 | F118: 0 | G118: 0 | H118: 80 | I118: 50 | J118: 0 | K118: 0 | L118: 30 | M118: 0 | N118: 0 | O118: 0 | P118: 0 | Q118: 25 | R118: 0 | S118: 0 | T118: 0 | U118: 0 | V118: 0 | W118: 80 | X118: 50 | Y118: 0 | Z118: 0 | AA118: 0 | AB118: 0 | AC118: 0 | AD118: 65 | AE118: 0 | AF118: 25 | AG118: 0 | AH118: 0 | AI118: =SUM(D118:AH118) -> 405
A119: 2212002015 | B119: MENUDO DE RES | C119: KG | D119: 0 | E119: 0 | F119: 0 | G119: 0 | H119: 0 | I119: 0 | J119: 0 | K119: 0 | L119: 0 | M119: 0 | N119: 0 | O119: 0 | P119: 0 | Q119: 0 | R119: 0 | S119: 0 | T119: 0 | U119: 0 | V119: 0 | W119: 0 | X119: 0 | Y119: 0 | Z119: 0 | AA119: 0 | AB119: 0 | AC119: 0 | AD119: 0 | AE119: 0 | AF119: 0 | AG119: 0 | AH119: 0 | AI119: =SUM(D119:AH119) -> 0
A120: 2212002019 | B120: BISTECK DE RES BOLA | C120: KG | D120: 0 | E120: 0 | F120: 0 | G120: 0 | H120: 0 | I120: 0 | J120: 0 | K120: 0 | L120: 0 | M120: 0 | N120: 0 | O120: 0 | P120: 0 | Q120: 0 | R120: 0 | S120: 0 | T120: 0 | U120: 0 | V120: 0 | W120: 0 | X120: 0 | Y120: 0 | Z120: 0 | AA120: 0 | AB120: 0 | AC120: 0 | AD120: 0 | AE120: 0 | AF120: 0 | AG120: 0 | AH120: 0 | AI120: =SUM(D120:AH120) -> 0
A121: 2212002020 | B121: COSTILLA DE RES CARGADA | C121: KG | D121: 0 | E121: 0 | F121: 0 | G121: 0 | H121: 0 | I121: 0 | J121: 0 | K121: 0 | L121: 0 | M121: 0 | N121: 0 | O121: 0 | P121: 0 | Q121: 80 | R121: 0 | S121: 0 | T121: 0 | U121: 0 | V121: 0 | W121: 0 | X121: 0 | Y121: 0 | Z121: 0 | AA121: 0 | AB121: 0 | AC121: 0 | AD121: 0 | AE121: 0 | AF121: 80 | AG121: 0 | AH121: 0 | AI121: =SUM(D121:AH121) -> 160
A122: 2212002021 | B122: FALDA DE RES EN TROZO | C122: KG | D122: 0 | E122: 0 | F122: 0 | G122: 0 | H122: 0 | I122: 0 | J122: 0 | K122: 0 | L122: 0 | M122: 0 | N122: 0 | O122: 0 | P122: 0 | Q122: 0 | R122: 0 | S122: 0 | T122: 0 | U122: 0 | V122: 0 | W122: 0 | X122: 0 | Y122: 0 | Z122: 0 | AA122: 0 | AB122: 0 | AC122: 0 | AD122: 0 | AE122: 0 | AF122: 0 | AG122: 0 | AH122: 0 | AI122: =SUM(D122:AH122) -> 0
...

Sheet COMEDOR
A1: CÓDIGO | B1: DESCRIPCIÓN | C1: UNIDAD DE MEDIDA | D1: 1 | E1: 2 | F1: 3 | G1: 4 | H1: 5 | I1: 6 | J1: 7 | K1: 8 | L1: 9 | M1: 10 | N1: 11 | O1: 12 | P1: 13 | Q1: 14 | R1: 15 | S1: 16 | T1: 17 | U1: 18 | V1: 19 | W1: 20 | X1: 21 | Y1: 22 | Z1: 23 | AA1: 24 | AB1: 25 | AC1: 26 | AD1: 27 | AE1: 28 | AF1: 29 | AG1: 30 | AH1: 31 | AI1: TOTAL
A3: GRUPO DE ALIMENTO: FRUTA
A4: 2212004001 | B4: CIRUELA ROJA | C4: KG | D4: 0 | E4: 0 | F4: 0 | G4: 0 | H4: 0 | I4: 0 | J4: 0 | K4: 0 | L4: 0 | M4: 0 | N4: 0 | O4: 0 | P4: 0 | Q4: 0 | R4: 0 | S4: 0 | T4: 0 | U4: 0 | V4: 0 | W4: 0 | X4: 0 | Y4: 0 | Z4: 0 | AA4: 0 | AB4: 0 | AC4: 0 | AD4: 0 | AE4: 0 | AF4: 0 | AG4: 0 | AH4: 0 | AI4: =SUM(D4:AH4) -> 0
A5: 2212004002 | B5: CAÑA DE AZUCAR | C5: PIEZA | D5: 0 | E5: 0 | F5: 0 | G5: 0 | H5: 0 | I5: 0 | J5: 0 | K5: 0 | L5: 0 | M5: 0 | N5: 0 | O5: 0 | P5: 0 | Q5: 0 | R5: 0 | S5: 0 | T5: 0 | U5: 0 | V5: 0 | W5: 0 | X5: 0 | Y5: 0 | Z5: 0 | AA5: 0 | AB5: 0 | AC5: 0 | AD5: 0 | AE5: 0 | AF5: 0 | AG5: 0 | AH5: 0 | AI5: =SUM(D5:AH5) -> 0
A6: 2212004003 | B6: CIRUELA AMARILLA | C6: KG | D6: 0 | E6: 0 | F6: 0 | G6: 0 | H6: 0 | I6: 0 | J6: 0 | K6: 0 | L6: 0 | M6: 0 | N6: 0 | O6: 0 | P6: 0 | Q6: 0 | R6: 0 | S6: 0 | T6: 0 | U6: 0 | V6: 0 | W6: 0 | X6: 0 | Y6: 0 | Z6: 0 | AA6: 0 | AB6: 0 | AC6: 0 | AD6: 0 | AE6: 0 | AF6: 0 | AG6: 0 | AH6: 0 | AI6: =SUM(D6:AH6) -> 0
A7: 2212004004 | B7: DURAZNO | C7: KG | D7: 30 | E7: 40 | F7: 0 | G7: 40 | H7: 0 | I7: 0 | J7: 0 | K7: 0 | L7: 0 | M7: 0 | N7: 0 | O7: 0 | P7: 0 | Q7: 0 | R7: 0 | S7: 0 | T7: 0 | U7: 0 | V7: 0 | W7: 0 | X7: 0 | Y7: 0 | Z7: 0 | AA7: 0 | AB7: 0 | AC7: 0 | AD7: 0 | AE7: 0 | AF7: 0 | AG7: 0 | AH7: 0 | AI7: =SUM(D7:AH7) -> 110
A8: 2212004005 | B8: FRESA | C8: KG | D8: 0 | E8: 0 | F8: 0 | G8: 0 | H8: 0 | I8: 0 | J8: 0 | K8: 0 | L8: 0 | M8: 0 | N8: 0 | O8: 0 | P8: 0 | Q8: 0 | R8: 0 | S8: 0 | T8: 0 | U8: 0 | V8: 0 | W8: 0 | X8: 0 | Y8: 0 | Z8: 0 | AA8: 0 | AB8: 0 | AC8: 0 | AD8: 0 | AE8: 0 | AF8: 0 | AG8: 0 | AH8: 0 | AI8: =SUM(D8:AH8) -> 0
A9: 2212004006 | B9: GUAYABA | C9: KG | D9: 0 | E9: 0 | F9: 0 | G9: 0 | H9: 0 | I9: 0 | J9: 0 | K9: 0 | L9: 0 | M9: 0 | N9: 0 | O9: 0 | P9: 0 | Q9: 0 | R9: 0 | S9: 0 | T9: 0 | U9: 0 | V9: 0 | W9: 0 | X9: 0 | Y9: 0 | Z9: 0 | AA9: 0 | AB9: 0 | AC9: 0 | AD9: 0 | AE9: 0 | AF9: 0 | AG9: 0 | AH9: 0 | AI9: =SUM(D9:AH9) -> 0
A10: 2212004007 | B10: JICAMA | C10: KG | D10: 0 | E10: 0 | F10: 0 | G10: 0 | H10: 0 | I10: 0 | J10: 0 | K10: 0 | L10: 0 | M10: 0 | N10: 0 | O10: 0 | P10: 0 | Q10: 0 | R10: 0 | S10: 0 | T10: 0 | U10: 0 | V10: 0 | W10: 0 | X10: 0 | Y10: 0 | Z10: 0 | AA10: 0 | AB10: 0 | AC10: 0 | AD10: 0 | AE10: 0 | AF10: 0 | AG10: 0 | AH10: 0 | AI10: =SUM(D10:AH10) -> 0
A11: 2212004008 | B11: LIMA | C11: KG | D11: 0 | E11: 0 | F11: 0 | G11: 0 | H11: 0 | I11: 0 | J11: 0 | K11: 0 | L11: 0 | M11: 0 | N11: 0 | O11: 0 | P11: 0 | Q11: 0 | R11: 0 | S11: 0 | T11: 0 | U11: 0 | V11: 0 | W11: 0 | X11: 0 | Y11: 0 | Z11: 0 | AA11: 0 | AB11: 0 | AC11: 0 | AD11: 0 | AE11: 0 | AF11: 0 | AG11: 0 | AH11: 0 | AI11: =SUM(D11:AH11) -> 0
A12: 2212004009 | B12: MANDARINA | C12: KG | D12: 0 | E12: 0 | F12: 0 | G12: 0 | H12: 0 | I12: 0 | J12: 0 | K12: 0 | L12: 0 | M12: 0 | N12: 0 | O12: 0 | P12: 0 | Q12: 0 | R12: 0 | S12: 0 | T12: 0 | U12: 0 | V12: 0 | W12: 0 | X12: 0 | Y12: 0 | Z12: 0 | AA12: 0 | AB12: 0 | AC12: 0 | AD12: 0 | AE12: 0 | AF12: 0 | AG12: 0 | AH12: 0 | AI12: =SUM(D12:AH12) -> 0
A13: 2212004011 | B13: MANZANA DELICIA | C13: KG | D13: 0 | E13: 20 | F13: 0 | G13: 0 | H13: 45 | I13: 20 | J13: 0 | K13: 0 | L13: 20 | M13: 0 | N13: 30 | O13: 0 | P13: 45 | Q13: 0 | R13: 0 | S13: 0 | T13: 0 | U13: 0 | V13: 70 | W13: 20 | X13: 20 | Y13: 0 | Z13: 20 | AA13: 0 | AB13: 20 | AC13: 30 | AD13: 0 | AE13: 0 | AF13: 0 | AG13: 0 | AH13: 0 | AI13: =SUM(D13:AH13) -> 360
A14: 2212004012 | B14: MANZANA GOLDEN | C14: KG | D14: 0 | E14: 0 | F14: 0 | G14: 0 | H14: 0 | I14: 0 | J14: 0 | K14: 0 | L14: 0 | M14: 0 | N14: 0 | O14: 0 | P14: 0 | Q14: 0 | R14: 0 | S14: 0 | T14: 0 | U14: 0 | V14: 0 | W14: 0 | X14: 0 | Y14: 0 | Z14: 0 | AA14: 0 | AB14: 0 | AC14: 0 | AD14: 0 | AE14: 0 | AF14: 0 | AG14: 0 | AH14: 0 | AI14: =SUM(D14:AH14) -> 0
A15: 2212004013 | B15: MELON CANTALUP | C15: KG | D15: 0 | E15: 0 | F15: 0 | G15: 0 | H15: 0 | I15: 0 | J15: 0 | K15: 0 | L15: 0 | M15: 0 | N15: 0 | O15: 0 | P15: 0 | Q15: 0 | R15: 0 | S15: 0 | T15: 0 | U15: 0 | V15: 0 | W15: 0 | X15: 0 | Y15: 0 | Z15: 0 | AA15: 0 | AB15: 0 | AC15: 0 | AD15: 0 | AE15: 0 | AF15: 0 | AG15: 0 | AH15: 0 | AI15: =SUM(D15:AH15) -> 0
... A34: 2212004038 | B34: GRANADA CHINA | C34: PIEZA | D34: 0 | E34: 0 | F34: 0 | G34: 0 | H34: 0 | I34: 0 | J34: 0 | K34: 0 | L34: 0 | M34: 0 | N34: 0 | O34: 0 | P34: 0 | Q34: 0 | R34: 0 | S34: 0 | T34: 0 | U34: 0 | V34: 0 | W34: 0 | X34: 0 | Y34: 0 | Z34: 0 | AA34: 0 | AB34: 0 | AC34: 0 | AD34: 0 | AE34: 0 | AF34: 0 | AG34: 0 | AH34: 0 | AI34: =SUM(D34:AH34) -> 0
A35: GRUPO DE ALIMENTO: VERDURA
A36: 2212010003 | B36: CHILE JALAPEÑO | C36: KG | D36: 0 | E36: 0 | F36: 0 | G36: 0 | H36: 0 | I36: 0 | J36: 0 | K36: 0 | L36: 0 | M36: 0 | N36: 0 | O36: 0 | P36: 0 | Q36: 0 | R36: 0 | S36: 0 | T36: 0 | U36: 0 | V36: 0 | W36: 0 | X36: 0 | Y36: 0 | Z36: 0 | AA36: 0 | AB36: 0 | AC36: 0 | AD36: 0 | AE36: 0 | AF36: 0 | AG36: 0 | AH36: 0 | AI36: =SUM(D36:AH36) -> 0
A37: 2212010004 | B37: CHAMPIÑONES | C37: KG | D37: 0 | E37: 0 | F37: 0 | G37: 0 | H37: 0 | I37: 0 | J37: 0 | K37: 0 | L37: 0 | M37: 0 | N37: 0 | O37: 0 | P37: 0 | Q37: 0 | R37: 0 | S37: 0 | T37: 0 | U37: 0 | V37: 0 | W37: 0 | X37: 0 | Y37: 0 | Z37: 0 | AA37: 0 | AB37: 0 | AC37: 0 | AD37: 0 | AE37: 0 | AF37: 0 | AG37: 0 | AH37: 0 | AI37: =SUM(D37:AH37) -> 0
A38: 2212010005 | B38: TE DE LIMON | C38: MANOJO | D38: 0 | E38: 0 | F38: 0 | G38: 0 | H38: 0 | I38: 0 | J38: 0 | K38: 0 | L38: 0 | M38: 0 | N38: 0 | O38: 0 | P38: 0 | Q38: 0 | R38: 0 | S38: 0 | T38: 0 | U38: 0 | V38: 0 | W38: 0 | X38: 0 | Y38: 0 | Z38: 0 | AA38: 0 | AB38: 0 | AC38: 0 | AD38: 0 | AE38: 0 | AF38: 0 | AG38: 0 | AH38: 0 | AI38: =SUM(D38:AH38) -> 0
A39: 2212010006 | B39: TOMILLO FRESCO | C39: MANOJO | D39: 0 | E39: 0 | F39: 0 | G39: 0 | H39: 0 | I39: 0 | J39: 0 | K39: 0 | L39: 0 | M39: 0 | N39: 0 | O39: 0 | P39: 0 | Q39: 0 | R39: 0 | S39: 0 | T39: 0 | U39: 0 | V39: 0 | W39: 0 | X39: 0 | Y39: 0 | Z39: 0 | AA39: 0 | AB39: 0 | AC39: 0 | AD39: 0 | AE39: 0 | AF39: 0 | AG39: 0 | AH39: 0 | AI39: =SUM(D39:AH39) -> 0
A40: 2212010007 | B40: ACELGA | C40: MANOJO | D40: 0 | E40: 0 | F40: 0 | G40: 0 | H40: 0 | I40: 0 | J40: 0 | K40: 0 | L40: 0 | M40: 0 | N40: 0 | O40: 0 | P40: 0 | Q40: 0 | R40: 0 | S40: 0 | T40: 0 | U40: 0 | V40: 0 | W40: 0 | X40: 0 | Y40: 0 | Z40: 0 | AA40: 0 | AB40: 0 | AC40: 0 | AD40: 0 | AE40: 0 | AF40: 0 | AG40: 0 | AH40: 0 | AI40: =SUM(D40:AH40) -> 0
A41: 2212010008 | B41: AGUACATE | C41: KG | D41: 10 | E41: 0 | F41: 10 | G41: 10 | H41: 0 | I41: 10 | J41: 0 | K41: 0 | L41: 10 | M41: 0 | N41: 0 | O41: 0 | P41: 0 | Q41: 0 | R41: 10 | S41: 0 | T41: 0 | U41: 5 | V41: 0 | W41: 10 | X41: 10 | Y41: 0 | Z41: 0 | AA41: 0 | AB41: 0 | AC41: 0 | AD41: 0 | AE41: 0 | AF41: 0 | AG41: 10 | AH41: 0 | AI41: =SUM(D41:AH41) -> 95
A42: 2212010009 | B42: APIO | C42: KG | D42: 0 | E42: 0 | F42: 0 | G42: 0 | H42: 0 | I42: 0 | J42: 0 | K42: 0 | L42: 0 | M42: 0 | N42: 1 | O42: 0 | P42: 0 | Q42: 0 | R42: 0 | S42: 0 | T42: 0 | U42: 0 | V42: 0 | W42: 0 | X42: 0 | Y42: 0 | Z42: 0 | AA42: 0 | AB42: 0 | AC42: 0 | AD42: 0 | AE42: 0 | AF42: 0 | AG42: 0 | AH42: 0 | AI42: =SUM(D42:AH42) -> 1
A43: 2212010010 | B43: BETABEL | C43: MANOJO | D43: 0 | E43: 0 | F43: 0 | G43: 0 | H43: 0 | I43: 0 | J43: 0 | K43: 0 | L43: 0 | M43: 0 | N43: 0 | O43: 0 | P43: 0 | Q43: 0 | R43: 0 | S43: 0 | T43: 0 | U43: 0 | V43: 0 | W43: 0 | X43: 0 | Y43: 0 | Z43: 0 | AA43: 0 | AB43: 0 | AC43: 0 | AD43: 0 | AE43: 0 | AF43: 0 | AG43: 0 | AH43: 0 | AI43: =SUM(D43:AH43) -> 0
A44: 2212010011 | B44: BROCOLI | C44: KG | D44: 0 | E44: 0 | F44: 0 | G44: 0 | H44: 0 | I44: 0 | J44: 0 | K44: 0 | L44: 0 | M44: 0 | N44: 0 | O44: 0 | P44: 0 | Q44: 0 | R44: 0 | S44: 0 | T44: 0 | U44: 0 | V44: 0 | W44: 0 | X44: 0 | Y44: 0 | Z44: 0 | AA44: 0 | AB44: 0 | AC44: 0 | AD44: 0 | AE44: 0 | AF44: 0 | AG44: 0 | AH44: 0 | AI44: =SUM(D44:AH44) -> 0
A45: 2212010012 | B45: CALABACITA ITALIANA | C45: KG | D45: 17 | E45: 7 | F45: 43 | G45: 7 | H45: 7 | I45: 15 | J45: 17 | K45: 5 | L45: 5 | M45: 5 | N45: 5 | O45: 10 | P45: 5 | Q45: 5 | R45: 7 | S45: 5 | T45: 0 | U45: 13 | V45: 7 | W45: 7 | X45: 35 | Y45: 5 | Z45: 5 | AA45: 5 | AB45: 7 | AC45: 5 | AD45: 5 | AE45: 5 | AF45: 7 | AG45: 17 | AH45: 0 | AI45: =SUM(D45:AH45) -> 288
A46: 2212010013 | B46: CALABAZA DURA | C46: KG | D46: 0 | E46: 0 | F46: 15 | G46: 0 | H46: 0 | I46: 0 | J46: 0 | K46: 0 | L46: 0 | M46: 0 | N46: 0 | O46: 0 | P46: 0 | Q46: 0 | R46: 0 | S46: 0 | T46: 0 | U46: 0 | V46: 0 | W46: 0 | X46: 0 | Y46: 0 | Z46: 0 | AA46: 0 | AB46: 0 | AC46: 0 | AD46: 0 | AE46: 0 | AF46: 0 | AG46: 0 | AH46: 0 | AI46: =SUM(D46:AH46) -> 15
A47: 2212010014 | B47: CAMOTE AMARILLO | C47: KG | D47: 0 | E47: 0 | F47: 0 | G47: 0 | H47: 0 | I47: 0 | J47: 0 | K47: 0 | L47: 0 | M47: 0 | N47: 0 | O47: 0 | P47: 0 | Q47: 0 | R47: 0 | S47: 0 | T47: 0 | U47: 0 | V47: 0 | W47: 0 | X47: 0 | Y47: 0 | Z47: 0 | AA47: 0 | AB47: 0 | AC47: 0 | AD47: 0 | AE47: 0 | AF47: 0 | AG47: 0 | AH47: 0 | AI47: =SUM(D47:AH47) -> 0
... A89: 2212004040 | B89: RABANO CHAMPION SIN RABO | C89: KG | D89: 0 | E89: 0 | F89: 0 | G89: 0 | H89: 0 | I89: 0 | J89: 0 | K89: 0 | L89: 0 | M89: 0 | N89: 0 | O89: 0 | P89: 0 | Q89: 0 | R89: 0 | S89: 0 | T89: 0 | U89: 0 | V89: 0 | W89: 0 | X89: 0 | Y89: 0 | Z89: 0 | AA89: 0 | AB89: 0 | AC89: 0 | AD89: 0 | AE89: 0 | AF89: 0 | AG89: 0 | AH89: 0 | AI89: =SUM(D89:AH89) -> 0
A90: GRUPO DE ALIMENTO: CERDO
A91: 2212002001 | B91: FAJITAS DE CERDO | C91: KG | D91: 0 | E91: 0 | F91: 0 | G91: 0 | H91: 0 | I91: 0 | J91: 0 | K91: 0 | L91: 0 | M91: 0 | N91: 0 | O91: 25 | P91: 0 | Q91: 0 | R91: 0 | S91: 0 | T91: 0 | U91: 0 | V91: 0 | W91: 0 | X91: 0 | Y91: 0 | Z91: 0 | AA91: 0 | AB91: 0 | AC91: 0 | AD91: 0 | AE91: 0 | AF91: 0 | AG91: 0 | AH91: 0 | AI91: =SUM(D91:AH91) -> 25
A92: 2212002004 | B92: CARNAZA DE CERDO EN TROZO | C92: KG | D92: 0 | E92: 0 | F92: 0 | G92: 0 | H92: 0 | I92: 0 | J92: 0 | K92: 0 | L92: 0 | M92: 0 | N92: 0 | O92: 0 | P92: 0 | Q92: 5 | R92: 10 | S92: 0 | T92: 0 | U92: 0 | V92: 0 | W92: 0 | X92: 0 | Y92: 0 | Z92: 0 | AA92: 0 | AB92: 0 | AC92: 0 | AD92: 0 | AE92: 0 | AF92: 0 | AG92: 5 | AH92: 0 | AI92: =SUM(D92:AH92) -> 20
A93: 2212002007 | B93: CARNE MOLIDA DE CERDO POCA GRASA | C93: KG | D93: 0 | E93: 0 | F93: 0 | G93: 0 | H93: 0 | I93: 0 | J93: 0 | K93: 30 | L93: 0 | M93: 0 | N93: 0 | O93: 0 | P93: 0 | Q93: 0 | R93: 0 | S93: 0 | T93: 0 | U93: 0 | V93: 0 | W93: 20 | X93: 0 | Y93: 0 | Z93: 0 | AA93: 40 | AB93: 0 | AC93: 30 | AD93: 0 | AE93: 0 | AF93: 0 | AG93: 0 | AH93: 0 | AI93: =SUM(D93:AH93) -> 120
A94: 2212002009 | B94: CHAMORRO DE CERDO PARTIDO | C94: KG | D94: 0 | E94: 0 | F94: 0 | G94: 0 | H94: 0 | I94: 0 | J94: 0 | K94: 0 | L94: 0 | M94: 0 | N94: 0 | O94: 0 | P94: 0 | Q94: 0 | R94: 7 | S94: 0 | T94: 0 | U94: 0 | V94: 0 | W94: 35 | X94: 0 | Y94: 0 | Z94: 0 | AA94: 0 | AB94: 0 | AC94: 0 | AD94: 0 | AE94: 0 | AF94: 0 | AG94: 0 | AH94: 0 | AI94: =SUM(D94:AH94) -> 42
A95: 2212002010 | B95: CHULETA DE CERDO AHUMADA CORTE DE 120GR C/U | C95: KG | D95: 0 | E95: 0 | F95: 0 | G95: 0 | H95: 0 | I95: 0 | J95: 0 | K95: 0 | L95: 0 | M95: 0 | N95: 0 | O95: 0 | P95: 0 | Q95: 0 | R95: 0 | S95: 0 | T95: 0 | U95: 0 | V95: 0 | W95: 0 | X95: 0 | Y95: 0 | Z95: 0 | AA95: 0 | AB95: 0 | AC95: 0 | AD95: 0 | AE95: 0 | AF95: 0 | AG95: 0 | AH95: 0 | AI95: =SUM(D95:AH95) -> 0
A96: 2212002011 | B96: COSTILLA DE CERDO EN TROCITO | C96: KG | D96: 0 | E96: 0 | F96: 0 | G96: 0 | H96: 0 | I96: 30 | J96: 0 | K96: 40 | L96: 0 | M96: 30 | N96: 0 | O96: 0 | P96: 0 | Q96: 35 | R96: 0 | S96: 0 | T96: 0 | U96: 0 | V96: 0 | W96: 0 | X96: 0 | Y96: 0 | Z96: 0 | AA96: 0 | AB96: 0 | AC96: 0 | AD96: 0 | AE96: 0 | AF96: 0 | AG96: 20 | AH96: 0 | AI96: =SUM(D96:AH96) -> 155
A97: 2212002014 | B97: LOMO DE CERDO | C97: KG | D97: 0 | E97: 0 | F97: 0 | G97: 0 | H97: 0 | I97: 0 | J97: 0 | K97: 0 | L97: 0 | M97: 0 | N97: 0 | O97: 0 | P97: 0 | Q97: 0 | R97: 0 | S97: 0 | T97: 0 | U97: 0 | V97: 0 | W97: 0 | X97: 0 | Y97: 0 | Z97: 0 | AA97: 0 | AB97: 0 | AC97: 0 | AD97: 0 | AE97: 0 | AF97: 0 | AG97: 0 | AH97: 0 | AI97: =SUM(D97:AH97) -> 0
A98: 2212002016 | B98: MILANESA DE CERDO | C98: KG | D98: 0 | E98: 0 | F98: 0 | G98: 0 | H98: 0 | I98: 0 | J98: 0 | K98: 0 | L98: 0 | M98: 0 | N98: 0 | O98: 0 | P98: 0 | Q98: 0 | R98: 0 | S98: 0 | T98: 0 | U98: 0 | V98: 0 | W98: 0 | X98: 0 | Y98: 0 | Z98: 0 | AA98: 0 | AB98: 0 | AC98: 0 | AD98: 0 | AE98: 0 | AF98: 0 | AG98: 0 | AH98: 0 | AI98: =SUM(D98:AH98) -> 0
A99: 2212002018 | B99: PIERNA DE CERDO EN TROZO CORTE DE 3 KILOS | C99: KG | D99: 0 | E99: 0 | F99: 0 | G99: 0 | H99: 0 | I99: 0 | J99: 0 | K99: 0 | L99: 0 | M99: 0 | N99: 0 | O99: 0 | P99: 40 | Q99: 0 | R99: 0 | S99: 0 | T99: 0 | U99: 0 | V99: 0 | W99: 0 | X99: 0 | Y99: 0 | Z99: 0 | AA99: 0 | AB99: 0 | AC99: 0 | AD99: 0 | AE99: 0 | AF99: 0 | AG99: 0 | AH99: 0 | AI99: =SUM(D99:AH99) -> 40
